Workbook

Sheet TOTAL 6 ZS
B8: PROVINCE DU KASAI CENTRAL
B9: DIVISION PROVINCIALE DE LA SANTE DU KASAI CENTRAL
B10: COORDINATION PROVINCE PEV KASAI CENTRAL
A11: ANTENNE PEV LUIZA
B12: FEVRIER 2026
A15: Antenne | B15: Zone de Santé | C15: Aires de santé | D15: Nbre des réfrigérateus solaire fonctionnel | E15: Nbre des réfrigérateurs solaire en panne | F15: Nbre des réfrigérateus à pétrole fonctionnel | G15: Nbre des réfrigérateus à pétrole en panne | H15: Nbre des Boites isothermes (BI) | J15: Doses VAR | K15: Nbre des glacières | L15: Nbre d'accumulateur | M15: Nbre des megaphones
H16: Petit format | I16: Grand format
A17: LUIZA | B17: Kalomba | C17: Aigle Bady
A18: LUIZA | B18: Kalomba | C18: Kalendende
A19: LUIZA | B19: Kalomba | C19: Kalomba
A20: LUIZA | B20: Kalomba | C20: Kankungula
A21: LUIZA | B21: Kalomba | C21: Kasanga Luebo
A22: LUIZA | B22: Kalomba | C22: Kasuku
A23: LUIZA | B23: Kalomba | C23: Katshiabala
A24: LUIZA | B24: Kalomba | C24: Mbuluku
A25: LUIZA | B25: Kalomba | C25: Mbunku
A26: LUIZA | B26: Kalomba | C26: Mfuamba
A27: LUIZA | B27: Kalomba | C27: Muendele
A28: LUIZA | B28: Kalomba | C28: Mutetela
... A33: LUIZA | B33: Kalomba | C33: Tshitadi
A34: LUIZA | C34: BUREAU CENTRAL
A35: TOTAL ZS KALOMBA | C35: 17 | D35: =SUM(D17:D34) | E35: =SUM(E17:E34) | F35: =SUM(F17:F34) | G35: =SUM(G17:G34) | H35: =SUM(H17:H34) | I35: =SUM(I17:I34) | J35: =SUM(J17:J34) | K35: =SUM(K17:K34) | ... M35: =SUM(M17:M34)
A36: LUIZA | B36: Luambo | C36: Biaboko
A37: LUIZA | B37: Luambo | C37: Kakela
A38: LUIZA | B38: Luambo | C38: Kalamba Mbuyi
A39: LUIZA | B39: Luambo | C39: Kambongo
A40: LUIZA | B40: Luambo | C40: Kangambo Baka
A41: LUIZA | B41: Luambo | C41: Kangambo Secteur
A42: LUIZA | B42: Luambo | C42: Kasombo Bishi
A43: LUIZA | B43: Luambo | C43: Kavueta
A44: LUIZA | B44: Luambo | C44: Luambo
A45: LUIZA | B45: Luambo | C45: Lueta
A46: LUIZA | B46: Luambo | C46: Lumpungu
A47: LUIZA | B47: Luambo | C47: Luyinda
... A61: LUIZA | B61: Luambo | C61: Tshikuni
A62: LUIZA | C62: BUREAU CENTRAL
A63: TOTAL ZS LUAMBO | C63: 26 | D63: =SUM(D36:D62) | E63: =SUM(E36:E62) | F63: =SUM(F36:F62) | G63: =SUM(G36:G62) | H63: =SUM(H36:H62) | I63: =SUM(I36:I62) | J63: =SUM(J36:J62) | K63: =SUM(K36:K62) | ... M63: =SUM(M36:M62)
A64: LUIZA | B64: Luiza | C64: Bambaie
A65: LUIZA | B65: Luiza | C65: Communautaire
A66: LUIZA | B66: Luiza | C66: Isasa
...

Sheet SYNTHESE 1
B8: PROVINCE DU KASAI CENTRAL
B9: DIVISION PROVINCIALE DE LA SANTE DU KASAI CENTRAL
B10: COORDINATION PROVINCE PEV KASAI CENTRAL
A11: ANTENNE PEV LUIZA
B12: FEVRIER 2026
A15: Antenne | B15: Zone de Santé | C15: Nbre D' Aire de Santé | D15: Nbre total des refrigerateurs solaire | E15: Nbre des réfrigérateus solaire fonctionnel | F15: Taux de fonctionnalité | G15: Nbre des réfrigérateurs solaire en panne | H15: Taux des réfrigérateurs solaire en panne | I15: Nbre des réfrigérateus à pétrole fonctionnel | J15: Nbre des réfrigérateus à pétrole en panne | K15: Nbre des Boites isothermes (BI) | M15: Doses VAR | N15: Nbre des glacières | O15: Nbre d'accumulateur | P15: Nbre des megaphones
K16: Petit format | L16: Grand format
A17: LUIZA | B17: Kalomba | C17: ='TOTAL 6 ZS'!C35 | D17: =E17+G17 | E17: ='TOTAL 6 ZS'!D35 | F17: =IFERROR(E17*100/D17,"") | G17: ='TOTAL 6 ZS'!E35 | H17: =IFERROR(G17*100/D17,"") | I17: ='TOTAL 6 ZS'!F35 | J17: ='TOTAL 6 ZS'!G35 | K17: ='TOTAL 6 ZS'!H35 | L17: ='TOTAL 6 ZS'!I35 | M17: ='TOTAL 6 ZS'!J35 | N17: ='TOTAL 6 ZS'!K35 | O17: ='TOTAL 6 ZS'!L35 | P17: ='TOTAL 6 ZS'!M35
A18: LUIZA | B18: Luambo | C18: ='TOTAL 6 ZS'!C63 | D18: =E18+G18 | E18: ='TOTAL 6 ZS'!D63 | F18: =IFERROR(E18*100/D18,"") | G18: ='TOTAL 6 ZS'!E63 | H18: =IFERROR(G18*100/D18,"") | I18: ='TOTAL 6 ZS'!F63 | J18: ='TOTAL 6 ZS'!G63 | K18: ='TOTAL 6 ZS'!H63 | L18: ='TOTAL 6 ZS'!I63 | M18: ='TOTAL 6 ZS'!J63 | N18: ='TOTAL 6 ZS'!K63 | O18: ='TOTAL 6 ZS'!L63 | P18: ='TOTAL 6 ZS'!M63
A19: LUIZA | B19: Luiza | C19: ='TOTAL 6 ZS'!C85 | D19: =E19+G19 | E19: ='TOTAL 6 ZS'!D85 | F19: =IFERROR(E19*100/D19,"") | G19: ='TOTAL 6 ZS'!E85 | H19: =IFERROR(G19*100/D19,"") | I19: ='TOTAL 6 ZS'!F85 | J19: ='TOTAL 6 ZS'!G85 | K19: ='TOTAL 6 ZS'!H85 | L19: ='TOTAL 6 ZS'!I85 | M19: ='TOTAL 6 ZS'!J85 | N19: ='TOTAL 6 ZS'!K85 | O19: ='TOTAL 6 ZS'!L85 | P19: ='TOTAL 6 ZS'!M85
A20: LUIZA | B20: Masuika | C20: ='TOTAL 6 ZS'!C110 | D20: =E20+G20 | E20: ='TOTAL 6 ZS'!D110 | F20: =IFERROR(E20*100/D20,"") | G20: ='TOTAL 6 ZS'!E110 | H20: =IFERROR(G20*100/D20,"") | I20: ='TOTAL 6 ZS'!F110 | J20: ='TOTAL 6 ZS'!G110 | K20: ='TOTAL 6 ZS'!H110 | L20: ='TOTAL 6 ZS'!I110 | M20: ='TOTAL 6 ZS'!J110 | N20: ='TOTAL 6 ZS'!K110 | O20: ='TOTAL 6 ZS'!L110 | P20: ='TOTAL 6 ZS'!M110
A21: LUIZA | B21: Tshibala | C21: ='TOTAL 6 ZS'!C139 | D21: =E21+G21 | E21: ='TOTAL 6 ZS'!D139 | F21: =IFERROR(E21*100/D21,"") | G21: ='TOTAL 6 ZS'!E139 | H21: =IFERROR(G21*100/D21,"") | I21: ='TOTAL 6 ZS'!F139 | J21: ='TOTAL 6 ZS'!G139 | K21: ='TOTAL 6 ZS'!H139 | L21: ='TOTAL 6 ZS'!I139 | M21: ='TOTAL 6 ZS'!J139 | N21: ='TOTAL 6 ZS'!K139 | O21: ='TOTAL 6 ZS'!L139 | P21: ='TOTAL 6 ZS'!M139
A22: LUIZA | B22: Yangala | C22: ='TOTAL 6 ZS'!C170 | D22: =E22+G22 | E22: ='TOTAL 6 ZS'!D170 | F22: =IFERROR(E22*100/D22,"") | G22: ='TOTAL 6 ZS'!E170 | H22: =IFERROR(G22*100/D22,"") | I22: ='TOTAL 6 ZS'!F170 | J22: ='TOTAL 6 ZS'!G170 | K22: ='TOTAL 6 ZS'!H170 | L22: ='TOTAL 6 ZS'!I170 | M22: ='TOTAL 6 ZS'!J170 | N22: ='TOTAL 6 ZS'!K170 | O22: ='TOTAL 6 ZS'!L170 | P22: ='TOTAL 6 ZS'!M170
A23: TOTAL ANTENNE PEV LUIZA | C23: =SUM(C17:C22) | D23: =E23+G23 | E23: =SUM(E17:E22) | F23: =IFERROR(E23*100/D23,"") | G23: =SUM(G17:G22) | H23: =IFERROR(G23*100/D23,"") | I23: =SUM(I17:I22) | J23: =SUM(J17:J22) | K23: =SUM(K17:K22) | L23: =SUM(L17:L22) | M23: =SUM(M17:M22) | N23: =SUM(N17:N22) | O23: =SUM(O17:O22) | P23: =SUM(P17:P22)

Sheet COUVERTURE EN REFRIGERAREUR 
B8: PROVINCE DU KASAI CENTRAL
B9: DIVISION PROVINCIALE DE LA SANTE DU KASAI CENTRAL
B10: COORDINATION PROVINCE PEV KASAI CENTRAL
A11: ANTENNE PEV LUIZA
B12: FEVRIER 2026
A15: Antenne | B15: Zone de Santé | C15: Nbre D' Aire de Santé | D15: Nbre D' Aire de Santé sans réfrigérateur | E15: Nbre D' Aire de Santé avec réfrigerateur | F15: Couverture en réfrigérateur(%) | G15: Nbre d' AS avec deux réfrigérateur
A16: LUIZA | B16: Kalomba | C16: ='TOTAL 6 ZS'!C35 | D16: =SUMPRODUCT((('TOTAL 6 ZS'!$D$17:$D$33+'TOTAL 6 ZS'!$E$17:$E$33+'TOTAL 6 ZS'!$F$17:$F$33+'TOTAL 6 ZS'!$G$17:$G$33)=0)*1) | E16: =C16-D16 | F16: =IFERROR(E16*100/C16,"") | G16: =SUMPRODUCT((('TOTAL 6 ZS'!$D$17:$D$33+'TOTAL 6 ZS'!$E$17:$E$33+'TOTAL 6 ZS'!$F$17:$F$33+'TOTAL 6 ZS'!$G$17:$G$33)>=2)*1)
A17: LUIZA | B17: Luambo | C17: ='TOTAL 6 ZS'!C63 | D17: =SUMPRODUCT((('TOTAL 6 ZS'!$D$36:$D$61+'TOTAL 6 ZS'!$E$36:$E$61+'TOTAL 6 ZS'!$F$36:$F$61+'TOTAL 6 ZS'!$G$36:$G$61)=0)*1) | E17: =C17-D17 | F17: =IFERROR(E17*100/C17,"") | G17: =SUMPRODUCT((('TOTAL 6 ZS'!$D$36:$D$61+'TOTAL 6 ZS'!$E$36:$E$61+'TOTAL 6 ZS'!$F$36:$F$61+'TOTAL 6 ZS'!$G$36:$G$61)>=2)*1)
A18: LUIZA | B18: Luiza | C18: ='TOTAL 6 ZS'!C85 | D18: =SUMPRODUCT((('TOTAL 6 ZS'!$D$64:$D$83+'TOTAL 6 ZS'!$E$64:$E$83+'TOTAL 6 ZS'!$F$64:$F$83+'TOTAL 6 ZS'!$G$64:$G$83)=0)*1) | E18: =C18-D18 | F18: =IFERROR(E18*100/C18,"") | G18: =SUMPRODUCT((('TOTAL 6 ZS'!$D$64:$D$83+'TOTAL 6 ZS'!$E$64:$E$83+'TOTAL 6 ZS'!$F$64:$F$83+'TOTAL 6 ZS'!$G$64:$G$83)>=2)*1)
A19: LUIZA | B19: Masuika | C19: ='TOTAL 6 ZS'!C110 | D19: =SUMPRODUCT((('TOTAL 6 ZS'!$D$86:$D$108+'TOTAL 6 ZS'!$E$86:$E$108+'TOTAL 6 ZS'!$F$86:$F$108+'TOTAL 6 ZS'!$G$86:$G$108)=0)*1) | E19: =C19-D19 | F19: =IFERROR(E19*100/C19,"") | G19: =SUMPRODUCT((('TOTAL 6 ZS'!$D$86:$D$108+'TOTAL 6 ZS'!$E$86:$E$108+'TOTAL 6 ZS'!$F$86:$F$108+'TOTAL 6 ZS'!$G$86:$G$108)>=2)*1)
A20: LUIZA | B20: Tshibala | C20: ='TOTAL 6 ZS'!C139 | D20: =SUMPRODUCT((('TOTAL 6 ZS'!$D$111:$D$137+'TOTAL 6 ZS'!$E$111:$E$137+'TOTAL 6 ZS'!$F$111:$F$137+'TOTAL 6 ZS'!$G$111:$G$137)=0)*1) | E20: =C20-D20 | F20: =IFERROR(E20*100/C20,"") | G20: =SUMPRODUCT((('TOTAL 6 ZS'!$D$111:$D$137+'TOTAL 6 ZS'!$E$111:$E$137+'TOTAL 6 ZS'!$F$111:$F$137+'TOTAL 6 ZS'!$G$111:$G$137)>=2)*1)
A21: LUIZA | B21: Yangala | C21: ='TOTAL 6 ZS'!C170 | D21: =SUMPRODUCT((('TOTAL 6 ZS'!$D$140:$D$168+'TOTAL 6 ZS'!$E$140:$E$168+'TOTAL 6 ZS'!$F$140:$F$168+'TOTAL 6 ZS'!$G$140:$G$168)=0)*1) | E21: =C21-D21 | F21: =IFERROR(E21*100/C21,"") | G21: =SUMPRODUCT((('TOTAL 6 ZS'!$D$140:$D$168+'TOTAL 6 ZS'!$E$140:$E$168+'TOTAL 6 ZS'!$F$140:$F$168+'TOTAL 6 ZS'!$G$140:$G$168)>=2)*1)
A22: TOTAL ANTENNE PEV LUIZA | C22: =SUM(C16:C21) | D22: =SUM(D16:D21) | E22: =C22-D22 | F22: =IFERROR(E22*100/C22,"") | G22: =SUM(G16:G21)
