Workbook
Name CV_ZS: Analyses_CV_ZS!$C$15:$AB$51
Name Segment_Antenne: #N/A
Name Segment_Categorisaton: #N/A
Name Segment_CV_Penta3: #N/A
Name Segment_Tx_Abandon: #N/A
Name Segment_ZS: #N/A

Sheet INSTRUCTIONS

Sheet Data_Entry
A1: Période cumulée : | C1: 10 | D1: ="Janvier-"&(_xlfn.IFS(Data_Entry!C1=1,"Janvier",Data_Entry!C1=2,"Février",Data_Entry!C1=3,"Mars",Data_Entry!C1=4,"Avril",Data_Entry!C1=5,"Mai",Data_Entry!C1=6,"Juin",Data_Entry!C1=7,"Juillet",Data_Entry!C1=8,"Août",Data_Entry!C1=9,"Septembre",Data_Entry!C1=10,"Octobre",Data_Entry!C1=11,"Novembre",Data_Entry!C1=12,"Décembre"))&" "&"2024" -> Janvier-Octobre 2024
A2: DONNEES BRUTES EXTRAITES DE DHIS2
AO3: PERFORMANCES MASHAKO / ZS | AY3: Mise à jour | AZ3: 45596
A4: Province | B4: Antenne | C4: ZS | D4: AS | E4: Pop_Totale_2024 | F4: Cible 3,49% | G4: Cible 4% | H4: Cible_Cumulée 3,49% | I4: Cible_Cumulée 4% | J4: BCG | K4: VPO 0 | L4: VPO 1 | M4: VPO 2 | N4: VPO 3 | O4: Penta 1 | P4: Penta 2 | Q4: Penta 3 | R4: PCV-13 (1) | S4: PCV-13 (2) | T4: PCV-13 (3) | U4: Rota 1 | V4: Rota 2 | W4: Rota 3 | X4: VAR1 | Y4: VAR 2/RR 2 | Z4: VAA | AA4: VPI1 | AB4: VPI 2 | AC4: Td 1 | AD4: Td 2 | AE4: Td 3 | AF4: Td 4 | AG4: Td 5 | AH4: Td2+ | AI4: Promptitude | AJ4: Completude | AK4: EZD | AL4: ESV | AM4: ECV | AO4: ZS | AP4: Supervision des Zones de Santé par la province | AQ4: Supervision ZS vers AS | AR4: Disponibilité des vaccins et intrants | AS4: Fonctionnalité de la CDF | AT4: Score de séances fixes | AU4: Score de séances avancées | AV4: Disponibilité des cartes de vaccinations | AW4: Suivi des enfants | AX4: Réunions | AY4: Rapport de données | AZ4: Score total
A5: Nord Kivu | B5: Butembo | C5: Alimbongo | D5: Alimbongo | E5: 12959 | F5: =IFERROR(E5*3.49%,"") -> 452.2691 | G5: =IFERROR(E5*4%,"") -> 518.36 | H5: =IFERROR((F5/12)*$C$1,"") -> 376.89092 | I5: =IFERROR((G5/12)*$C$1,"") -> 431.96667 | J5: 371 | K5: 209 | L5: 429 | M5: 390 | N5: 399 | O5: 406 | P5: 367 | Q5: 367 | R5: 354 | S5: 304 | T5: 296 | U5: 386 | V5: 360 | W5: 358 | X5: 388 | Y5: 146 | Z5: 379 | AA5: 397 | AB5: 390 | AC5: 161 | AD5: 108 | AE5: 102 | AF5: 152 | AG5: 71 | AH5: =SUM(Tableau2[[#This Row],[Td 2]:[Td 5]]) -> 433 | AI5: 58.3 | AJ5: 100 | AK5: =IFERROR(IF(H5-O5<0,0,H5-O5),0) -> 0 | AL5: =IFERROR(IF(O5-X5<0,0,O5-X5),0) -> 18 | AM5: =MIN(X5,Z5) -> 379 | AO5: Alimbongo | AQ5: 0.61904762 | AR5: 0.69230769 | AS5: 1 | AT5: 0.38461538 | AU5: 0.77777778 | AV5: 1 | AW5: 0.38461538 | AY5: 0 | AZ5: 0.60952381
A6: Nord Kivu | B6: Butembo | C6: Alimbongo | D6: Bingi | E6: 14117 | F6: =IFERROR(E6*3.49%,"") -> 492.6833 | G6: =IFERROR(E6*4%,"") -> 564.68 | H6: =IFERROR((F6/12)*$C$1,"") -> 410.56942 | I6: =IFERROR((G6/12)*$C$1,"") -> 470.56667 | J6: 490 | K6: 1398 | L6: 617 | M6: 453 | N6: 595 | O6: 617 | P6: 452 | Q6: 595 | R6: 559 | S6: 420 | T6: 539 | U6: 617 | V6: 460 | W6: 600 | X6: 583 | Y6: 177 | Z6: 583 | AA6: 892 | AB6: 583 | AC6: 224 | AD6: 130 | AE6: 154 | AF6: 138 | AG6: 150 | AH6: =SUM(Tableau2[[#This Row],[Td 2]:[Td 5]]) -> 572 | AI6: 62.5 | AJ6: 100 | AK6: =IFERROR(IF(H6-O6<0,0,H6-O6),0) -> 0 | AL6: =IFERROR(IF(O6-X6<0,0,O6-X6),0) -> 34 | AM6: =MIN(X6,Z6) -> 583 | AO6: Bambo | AQ6: 0.92307692 | AR6: 1 | AS6: 1 | AT6: 0.25 | AU6: 1 | AV6: 1 | AW6: 1 | AY6: 0 | AZ6: 0.77596154
A7: Nord Kivu | B7: Butembo | C7: Alimbongo | D7: Bunyatenge | E7: 17821 | F7: =IFERROR(E7*3.49%,"") -> 621.9529 | G7: =IFERROR(E7*4%,"") -> 712.84 | H7: =IFERROR((F7/12)*$C$1,"") -> 518.29408 | I7: =IFERROR((G7/12)*$C$1,"") -> 594.03333 | J7: 415 | K7: 408 | L7: 631 | M7: 604 | N7: 594 | O7: 555 | P7: 543 | Q7: 517 | R7: 576 | S7: 551 | T7: 527 | U7: 631 | V7: 610 | W7: 589 | X7: 615 | Y7: 357 | Z7: 547 | AA7: 602 | AB7: 421 | AC7: 264 | AD7: 130 | AE7: 86 | AF7: 90 | AG7: 129 | AH7: =SUM(Tableau2[[#This Row],[Td 2]:[Td 5]]) -> 435 | AI7: 62.5 | AJ7: 100 | AK7: =IFERROR(IF(H7-O7<0,0,H7-O7),0) -> 0 | AL7: =IFERROR(IF(O7-X7<0,0,O7-X7),0) -> 0 | AM7: =MIN(X7,Z7) -> 547 | AO7: Beni | AQ7: 0 | AR7: 0 | AS7: 0 | AT7: 0 | AY7: 0 | AZ7: 0
A8: Nord Kivu | B8: Butembo | C8: Alimbongo | D8: Caritas Kaseghe | E8: 14630 | F8: =IFERROR(E8*3.49%,"") -> 510.587 | G8: =IFERROR(E8*4%,"") -> 585.2 | H8: =IFERROR((F8/12)*$C$1,"") -> 425.48917 | I8: =IFERROR((G8/12)*$C$1,"") -> 487.66667 | J8: 278 | K8: 14 | L8: 255 | M8: 226 | N8: 187 | O8: 262 | P8: 222 | Q8: 181 | R8: 201 | S8: 230 | T8: 193 | U8: 259 | V8: 243 | W8: 214 | X8: 296 | Y8: 74 | Z8: 247 | AA8: 208 | AB8: 186 | AC8: 103 | AD8: 87 | AE8: 43 | AF8: 37 | AG8: 33 | AH8: =SUM(Tableau2[[#This Row],[Td 2]:[Td 5]]) -> 200 | AI8: 54.2 | AJ8: 100 | AK8: =IFERROR(IF(H8-O8<0,0,H8-O8),0) -> 163.48917 | AL8: =IFERROR(IF(O8-X8<0,0,O8-X8),0) -> 0 | AM8: =MIN(X8,Z8) -> 247 | AO8: Biena | AQ8: 0.75 | AR8: 0.36363636 | AS8: 0.90909091 | AT8: 0.41666667 | AU8: 0.75 | AV8: 0.75 | AW8: 0.41666667 | AY8: 0 | AZ8: 0.52765152
A9: Nord Kivu | B9: Butembo | C9: Alimbongo | D9: Fatua | E9: 7629 | F9: =IFERROR(E9*3.49%,"") -> 266.2521 | G9: =IFERROR(E9*4%,"") -> 305.16 | H9: =IFERROR((F9/12)*$C$1,"") -> 221.87675 | I9: =IFERROR((G9/12)*$C$1,"") -> 254.3 | K9: 141 | L9: 177 | M9: 155 | N9: 150 | O9: 181 | P9: 180 | Q9: 171 | R9: 198 | S9: 141 | T9: 139 | U9: 140 | V9: 123 | W9: 137 | X9: 218 | Y9: 148 | Z9: 227 | AA9: 195 | AB9: 102 | AC9: 179 | AD9: 85 | AE9: 77 | AF9: 58 | AG9: 62 | AH9: =SUM(Tableau2[[#This Row],[Td 2]:[Td 5]]) -> 282 | AI9: 58.3 | AJ9: 100 | AK9: =IFERROR(IF(H9-O9<0,0,H9-O9),0) -> 40.87675 | AL9: =IFERROR(IF(O9-X9<0,0,O9-X9),0) -> 0 | AM9: =MIN(X9,Z9) -> 218 | AO9: Binza | AQ9: 0.35714286 | AR9: 0.66666667 | AS9: 1 | AT9: 1 | AU9: 1 | AV9: 0.6 | AW9: 0.8 | AY9: 0 | AZ9: 0.6902381
A10: Nord Kivu | B10: Butembo | C10: Alimbongo | D10: Itundwe | E10: 10164 | F10: =IFERROR(E10*3.49%,"") -> 354.7236 | G10: =IFERROR(E10*4%,"") -> 406.56 | H10: =IFERROR((F10/12)*$C$1,"") -> 295.603 | I10: =IFERROR((G10/12)*$C$1,"") -> 338.8 | J10: 198 | K10: 105 | L10: 391 | M10: 384 | N10: 403 | O10: 387 | P10: 377 | Q10: 370 | R10: 347 | S10: 331 | T10: 376 | U10: 405 | V10: 380 | W10: 414 | X10: 436 | Y10: 106 | Z10: 435 | AA10: 423 | AB10: 341 | AC10: 112 | AD10: 55 | AE10: 69 | AF10: 38 | AG10: 26 | AH10: =SUM(Tableau2[[#This Row],[Td 2]:[Td 5]]) -> 188 | AI10: 50 | AJ10: 100 | AK10: =IFERROR(IF(H10-O10<0,0,H10-O10),0) -> 0 | AL10: =IFERROR(IF(O10-X10<0,0,O10-X10),0) -> 0 | AM10: =MIN(X10,Z10) -> 435 | AO10: Birambizo | AQ10: 0.5 | AR10: 0.75 | AS10: 0.75 | AT10: 0.14285714 | AU10: 1 | AV10: 0.42857143 | AW10: 0.71428571 | AY10: 0 | AZ10: 0.56607143
A11: Nord Kivu | B11: Butembo | C11: Alimbongo | D11: Kalimba | E11: 10467 | F11: =IFERROR(E11*3.49%,"") -> 365.2983 | G11: =IFERROR(E11*4%,"") -> 418.68 | H11: =IFERROR((F11/12)*$C$1,"") -> 304.41525 | I11: =IFERROR((G11/12)*$C$1,"") -> 348.9 | J11: 236 | K11: 439 | L11: 313 | M11: 298 | N11: 348 | O11: 340 | P11: 329 | Q11: 329 | R11: 306 | S11: 287 | T11: 306 | U11: 357 | V11: 337 | W11: 357 | X11: 401 | Y11: 263 | Z11: 366 | AA11: 245 | AB11: 207 | AC11: 81 | AD11: 52 | AE11: 53 | AF11: 42 | AG11: 24 | AH11: =SUM(Tableau2[[#This Row],[Td 2]:[Td 5]]) -> 171 | AI11: 62.5 | AJ11: 100 | AK11: =IFERROR(IF(H11-O11<0,0,H11-O11),0) -> 0 | AL11: =IFERROR(IF(O11-X11<0,0,O11-X11),0) -> 0 | AM11: =MIN(X11,Z11) -> 366 | AO11: Butembo | AQ11: 0.875 | AR11: 0.5 | AS11: 1 | AT11: 0.64285714 | AU11: 1 | AV11: 0.85714286 | AW11: 0.42857143 | AY11: 0 | AZ11: 0.66696429
A12: Nord Kivu | B12: Butembo | C12: Alimbongo | D12: Kalungu | E12: 18343 | F12: =IFERROR(E12*3.49%,"") -> 640.1707 | G12: =IFERROR(E12*4%,"") -> 733.72 | H12: =IFERROR((F12/12)*$C$1,"") -> 533.47558 | I12: =IFERROR((G12/12)*$C$1,"") -> 611.43333 | J12: 354 | K12: 642 | L12: 540 | M12: 527 | N12: 541 | O12: 539 | P12: 530 | Q12: 540 | R12: 540 | S12: 529 | T12: 487 | U12: 540 | V12: 529 | W12: 542 | X12: 639 | Y12: 206 | Z12: 629 | AA12: 487 | AB12: 274 | AC12: 696 | AD12: 392 | AE12: 353 | AF12: 315 | AG12: 128 | AH12: =SUM(Tableau2[[#This Row],[Td 2]:[Td 5]]) -> 1188 | AI12: 52.8 | AJ12: 100 | AK12: =IFERROR(IF(H12-O12<0,0,H12-O12),0) -> 0 | AL12: =IFERROR(IF(O12-X12<0,0,O12-X12),0) -> 0 | AM12: =MIN(X12,Z12) -> 629 | AO12: Goma | AQ12: 0.5 | AR12: 1 | AS12: 1 | AT12: 0.2 | AV12: 0.8 | AW12: 0.6 | AY12: 0 | AZ12: 0.61764706
A13: Nord Kivu | B13: Butembo | C13: Alimbongo | D13: Kaseghe CBCA | E13: 9186 | F13: =IFERROR(E13*3.49%,"") -> 320.5914 | G13: =IFERROR(E13*4%,"") -> 367.44 | H13: =IFERROR((F13/12)*$C$1,"") -> 267.1595 | I13: =IFERROR((G13/12)*$C$1,"") -> 306.2 | J13: 12 | K13: 7 | L13: 288 | M13: 276 | N13: 293 | O13: 208 | P13: 197 | Q13: 215 | R13: 213 | S13: 202 | T13: 220 | U13: 240 | V13: 204 | W13: 221 | X13: 267 | Y13: 35 | Z13: 263 | AA13: 306 | AB13: 254 | AC13: 191 | AD13: 135 | AE13: 99 | AF13: 78 | AG13: 45 | AH13: =SUM(Tableau2[[#This Row],[Td 2]:[Td 5]]) -> 357 | AI13: 50 | AJ13: 100 | AK13: =IFERROR(IF(H13-O13<0,0,H13-O13),0) -> 59.1595 | AL13: =IFERROR(IF(O13-X13<0,0,O13-X13),0) -> 0 | AM13: =MIN(X13,Z13) -> 263 | AO13: Itebero | AQ13: 0.033333333 | AR13: 1 | AS13: 1 | AT13: 0 | AV13: 0 | AW13: 1 | AY13: 0 | AZ13: 0.47647059
A14: Nord Kivu | B14: Butembo | C14: Alimbongo | D14: Kasingiri | E14: 12955 | F14: =IFERROR(E14*3.49%,"") -> 452.1295 | G14: =IFERROR(E14*4%,"") -> 518.2 | H14: =IFERROR((F14/12)*$C$1,"") -> 376.77458 | I14: =IFERROR((G14/12)*$C$1,"") -> 431.83333 | J14: 283 | K14: 121 | L14: 178 | M14: 165 | N14: 167 | O14: 301 | P14: 291 | Q14: 269 | R14: 299 | S14: 282 | T14: 265 | U14: 333 | V14: 295 | W14: 309 | X14: 406 | Y14: 174 | Z14: 304 | AA14: 256 | AB14: 167 | AC14: 31 | AD14: 18 | AE14: 35 | AF14: 29 | AG14: 24 | AH14: =SUM(Tableau2[[#This Row],[Td 2]:[Td 5]]) -> 106 | AI14: 54.2 | AJ14: 100 | AK14: =IFERROR(IF(H14-O14<0,0,H14-O14),0) -> 75.774583 | AL14: =IFERROR(IF(O14-X14<0,0,O14-X14),0) -> 0 | AM14: =MIN(X14,Z14) -> 304 | AO14: Kalunguta | AQ14: 0.33333333 | AR14: 0.66666667 | AS14: 1 | AT14: 0.33333333 | AU14: 1 | AV14: 1 | AW14: 0.66666667 | AY14: 0 | AZ14: 0.6
A15: Nord Kivu | B15: Butembo | C15: Alimbongo | D15: Kikyo | E15: 13850 | F15: =IFERROR(E15*3.49%,"") -> 483.365 | G15: =IFERROR(E15*4%,"") -> 554 | H15: =IFERROR((F15/12)*$C$1,"") -> 402.80417 | I15: =IFERROR((G15/12)*$C$1,"") -> 461.66667 | J15: 128 | L15: 166 | M15: 158 | N15: 163 | O15: 169 | P15: 159 | Q15: 147 | R15: 171 | S15: 158 | T15: 148 | U15: 160 | V15: 152 | W15: 154 | X15: 167 | Y15: 30 | Z15: 166 | AA15: 164 | AB15: 156 | AC15: 77 | AD15: 40 | AE15: 17 | AF15: 11 | AG15: 16 | AH15: =SUM(Tableau2[[#This Row],[Td 2]:[Td 5]]) -> 84 | AI15: 45.8 | AJ15: 100 | AK15: =IFERROR(IF(H15-O15<0,0,H15-O15),0) -> 233.80417 | AL15: =IFERROR(IF(O15-X15<0,0,O15-X15),0) -> 2 | AM15: =MIN(X15,Z15) -> 166 | AO15: Kamango | AQ15: 0.14285714 | AR15: 0 | AS15: 0 | AT15: 0.5 | AU15: 1 | AV15: 0 | AW15: 0.5 | AY15: 0 | AZ15: 0.27142857
A16: Nord Kivu | B16: Butembo | C16: Alimbongo | D16: Kilonge | E16: 10570 | F16: =IFERROR(E16*3.49%,"") -> 368.893 | G16: =IFERROR(E16*4%,"") -> 422.8 | H16: =IFERROR((F16/12)*$C$1,"") -> 307.41083 | I16: =IFERROR((G16/12)*$C$1,"") -> 352.33333 | J16: 231 | K16: 191 | L16: 368 | M16: 350 | N16: 335 | O16: 366 | P16: 354 | Q16: 334 | R16: 317 | S16: 320 | T16: 283 | U16: 356 | V16: 306 | W16: 315 | X16: 358 | Y16: 63 | Z16: 311 | AA16: 265 | AB16: 201 | AC16: 562 | AD16: 354 | AE16: 190 | AF16: 125 | AG16: 108 | AH16: =SUM(Tableau2[[#This Row],[Td 2]:[Td 5]]) -> 777 | AI16: 58.3 | AJ16: 100 | AK16: =IFERROR(IF(H16-O16<0,0,H16-O16),0) -> 0 | AL16: =IFERROR(IF(O16-X16<0,0,O16-X16),0) -> 8 | AM16: =MIN(X16,Z16) -> 311 | AO16: Karisimbi | AQ16: 0 | AR16: 0 | AS16: 0 | AT16: 0 | AY16: 0 | AZ16: 0
A17: Nord Kivu | B17: Butembo | C17: Alimbongo | D17: Kiribata | E17: 8336 | F17: =IFERROR(E17*3.49%,"") -> 290.9264 | G17: =IFERROR(E17*4%,"") -> 333.44 | H17: =IFERROR((F17/12)*$C$1,"") -> 242.43867 | I17: =IFERROR((G17/12)*$C$1,"") -> 277.86667 | J17: 226 | K17: 31 | L17: 268 | M17: 254 | N17: 258 | O17: 293 | P17: 272 | Q17: 270 | R17: 283 | S17: 271 | T17: 268 | U17: 239 | V17: 240 | W17: 224 | X17: 274 | Y17: 109 | Z17: 264 | AA17: 225 | AB17: 215 | AC17: 77 | AD17: 57 | AE17: 63 | AF17: 60 | AG17: 63 | AH17: =SUM(Tableau2[[#This Row],[Td 2]:[Td 5]]) -> 243 | AI17: 58.3 | AJ17: 100 | AK17: =IFERROR(IF(H17-O17<0,0,H17-O17),0) -> 0 | AL17: =IFERROR(IF(O17-X17<0,0,O17-X17),0) -> 19 | AM17: =MIN(X17,Z17) -> 264 | AO17: Katoyi | AQ17: 1 | AR17: 0.15789474 | AS17: 0.94736842 | AT17: 0.14285714 | AU17: 1 | AV17: 0.57142857 | AW17: 0 | AY17: 0 | AZ17: 0.48421053
A18: Nord Kivu | B18: Butembo | C18: Alimbongo | D18: Kitsombiro | E18: 17192 | F18: =IFERROR(E18*3.49%,"") -> 600.0008 | G18: =IFERROR(E18*4%,"") -> 687.68 | H18: =IFERROR((F18/12)*$C$1,"") -> 500.00067 | I18: =IFERROR((G18/12)*$C$1,"") -> 573.06667 | J18: 454 | K18: 428 | L18: 425 | M18: 402 | N18: 395 | O18: 432 | P18: 404 | Q18: 387 | R18: 435 | S18: 419 | T18: 391 | U18: 368 | V18: 299 | W18: 212 | X18: 508 | Y18: 170 | Z18: 435 | AA18: 397 | AB18: 260 | AC18: 172 | AD18: 140 | AE18: 101 | AF18: 92 | AG18: 243 | AH18: =SUM(Tableau2[[#This Row],[Td 2]:[Td 5]]) -> 576 | AI18: 58.3 | AJ18: 100 | AK18: =IFERROR(IF(H18-O18<0,0,H18-O18),0) -> 68.000667 | AL18: =IFERROR(IF(O18-X18<0,0,O18-X18),0) -> 0 | AM18: =MIN(X18,Z18) -> 435 | AO18: Katwa | AQ18: 0.65 | AR18: 0.625 | AS18: 1 | AT18: 0.30769231 | AU18: 1 | AV18: 0.46153846 | AW18: 0.76923077 | AY18: 0 | AZ18: 0.61144231
A19: Nord Kivu | B19: Butembo | C19: Alimbongo | D19: Kyambali | E19: 11082 | F19: =IFERROR(E19*3.49%,"") -> 386.7618 | G19: =IFERROR(E19*4%,"") -> 443.28 | H19: =IFERROR((F19/12)*$C$1,"") -> 322.3015 | I19: =IFERROR((G19/12)*$C$1,"") -> 369.4 | J19: 188 | K19: 28 | L19: 187 | M19: 172 | N19: 190 | O19: 178 | P19: 170 | Q19: 183 | R19: 174 | S19: 149 | T19: 173 | U19: 182 | V19: 177 | W19: 187 | X19: 231 | Y19: 55 | Z19: 208 | AA19: 212 | AB19: 232 | AC19: 42 | AD19: 4 | AE19: 9 | AF19: 29 | AG19: 35 | AH19: =SUM(Tableau2[[#This Row],[Td 2]:[Td 5]]) -> 77 | AI19: 50 | AJ19: 100 | AK19: =IFERROR(IF(H19-O19<0,0,H19-O19),0) -> 144.3015 | AL19: =IFERROR(IF(O19-X19<0,0,O19-X19),0) -> 0 | AM19: =MIN(X19,Z19) -> 208 | AO19: Kayna | AQ19: 0.043478261 | AR19: 0 | AS19: 0 | AT19: 1 | AV19: 0 | AW19: 1 | AY19: 0 | AZ19: 0.24296675
A20: Nord Kivu | B20: Butembo | C20: Alimbongo | D20: Lubango | E20: 16481 | F20: =IFERROR(E20*3.49%,"") -> 575.1869 | G20: =IFERROR(E20*4%,"") -> 659.24 | H20: =IFERROR((F20/12)*$C$1,"") -> 479.32242 | I20: =IFERROR((G20/12)*$C$1,"") -> 549.36667 | J20: 565 | K20: 596 | L20: 534 | M20: 521 | N20: 543 | O20: 519 | P20: 487 | Q20: 492 | R20: 507 | S20: 462 | T20: 457 | U20: 538 | V20: 486 | W20: 505 | X20: 540 | Y20: 167 | Z20: 563 | AA20: 547 | AB20: 443 | AC20: 490 | AD20: 340 | AE20: 126 | AF20: 75 | AG20: 25 | AH20: =SUM(Tableau2[[#This Row],[Td 2]:[Td 5]]) -> 566 | AI20: 58.3 | AJ20: 100 | AK20: =IFERROR(IF(H20-O20<0,0,H20-O20),0) -> 0 | AL20: =IFERROR(IF(O20-X20<0,0,O20-X20),0) -> 0 | AM20: =MIN(X20,Z20) -> 540 | AO20: Kibirizi | AQ20: 0.75 | AR20: 0.41176471 | AS20: 0.94117647 | AT20: 0.33333333 | AU20: 1 | AV20: 0.77777778 | AW20: 0.38888889 | AY20: 0 | AZ20: 0.56789216
A21: Nord Kivu | B21: Butembo | C21: Alimbongo | D21: Lunyasenge | E21: 13216 | F21: =IFERROR(E21*3.49%,"") -> 461.2384 | G21: =IFERROR(E21*4%,"") -> 528.64 | H21: =IFERROR((F21/12)*$C$1,"") -> 384.36533 | I21: =IFERROR((G21/12)*$C$1,"") -> 440.53333 | J21: 340 | K21: 284 | L21: 289 | M21: 231 | N21: 257 | O21: 299 | P21: 267 | Q21: 244 | R21: 260 | S21: 233 | T21: 221 | U21: 323 | V21: 256 | W21: 256 | X21: 337 | Y21: 90 | Z21: 298 | AA21: 227 | AB21: 228 | AC21: 169 | AD21: 90 | AE21: 32 | AF21: 18 | AG21: 22 | AH21: =SUM(Tableau2[[#This Row],[Td 2]:[Td 5]]) -> 162 | AI21: 66.7 | AJ21: 100 | AK21: =IFERROR(IF(H21-O21<0,0,H21-O21),0) -> 85.365333 | AL21: =IFERROR(IF(O21-X21<0,0,O21-X21),0) -> 0 | AM21: =MIN(X21,Z21) -> 298 | AO21: Kibua | AQ21: 0.15789474 | AR21: 1 | AS21: 1 | AT21: 0 | AU21: 1 | AV21: 0.33333333 | AW21: 0 | AY21: 0 | AZ21: 0.54035088
A22: Nord Kivu | B22: Butembo | C22: Alimbongo | D22: Luseke | E22: 17854 | F22: =IFERROR(E22*3.49%,"") -> 623.1046 | G22: =IFERROR(E22*4%,"") -> 714.16 | H22: =IFERROR((F22/12)*$C$1,"") -> 519.25383 | I22: =IFERROR((G22/12)*$C$1,"") -> 595.13333 | J22: 494 | K22: 436 | L22: 388 | M22: 407 | N22: 374 | O22: 442 | P22: 444 | Q22: 421 | R22: 430 | S22: 425 | T22: 413 | U22: 409 | V22: 425 | W22: 461 | X22: 585 | Y22: 218 | Z22: 534 | AA22: 470 | AB22: 333 | AC22: 169 | AD22: 107 | AE22: 128 | AF22: 124 | AG22: 103 | AH22: =SUM(Tableau2[[#This Row],[Td 2]:[Td 5]]) -> 462 | AI22: 58.3 | AJ22: 100 | AK22: =IFERROR(IF(H22-O22<0,0,H22-O22),0) -> 77.253833 | AL22: =IFERROR(IF(O22-X22<0,0,O22-X22),0) -> 0 | AM22: =MIN(X22,Z22) -> 534 | AO22: Kirotshe | AQ22: 0 | AR22: 0 | AS22: 0 | AT22: 0 | AY22: 0 | AZ22: 0
A23: Nord Kivu | B23: Butembo | C23: Alimbongo | D23: Masika | E23: 8599 | F23: =IFERROR(E23*3.49%,"") -> 300.1051 | G23: =IFERROR(E23*4%,"") -> 343.96 | H23: =IFERROR((F23/12)*$C$1,"") -> 250.08758 | I23: =IFERROR((G23/12)*$C$1,"") -> 286.63333 | J23: 283 | K23: 254 | L23: 475 | M23: 379 | N23: 346 | O23: 446 | P23: 351 | Q23: 274 | R23: 412 | S23: 342 | T23: 289 | U23: 385 | V23: 300 | W23: 242 | X23: 315 | Y23: 213 | Z23: 315 | AA23: 294 | AB23: 202 | AC23: 64 | AD23: 87 | AE23: 95 | AF23: 51 | AG23: 48 | AH23: =SUM(Tableau2[[#This Row],[Td 2]:[Td 5]]) -> 281 | AI23: 58.3 | AJ23: 100 | AK23: =IFERROR(IF(H23-O23<0,0,H23-O23),0) -> 0 | AL23: =IFERROR(IF(O23-X23<0,0,O23-X23),0) -> 131 | AM23: =MIN(X23,Z23) -> 315 | AO23: Kyondo | AQ23: 0.39130435 | AR23: 0.71428571 | AS23: 1 | AT23: 0.55555556 | AU23: 1 | AV23: 0.77777778 | AW23: 0.88888889 | AY23: 0 | AZ23: 0.65393375
A24: Nord Kivu | B24: Butembo | C24: Alimbongo | D24: Matembe | E24: 9885 | F24: =IFERROR(E24*3.49%,"") -> 344.9865 | G24: =IFERROR(E24*4%,"") -> 395.4 | H24: =IFERROR((F24/12)*$C$1,"") -> 287.48875 | I24: =IFERROR((G24/12)*$C$1,"") -> 329.5 | J24: 91 | K24: 106 | L24: 189 | M24: 148 | N24: 180 | O24: 168 | P24: 124 | Q24: 180 | R24: 168 | S24: 124 | T24: 160 | U24: 184 | V24: 144 | W24: 170 | X24: 215 | Y24: 41 | Z24: 213 | AA24: 180 | AB24: 179 | AC24: 63 | AD24: 38 | AE24: 17 | AF24: 22 | AG24: 20 | AH24: =SUM(Tableau2[[#This Row],[Td 2]:[Td 5]]) -> 97 | AI24: 54.2 | AJ24: 100 | AK24: =IFERROR(IF(H24-O24<0,0,H24-O24),0) -> 119.48875 | AL24: =IFERROR(IF(O24-X24<0,0,O24-X24),0) -> 0 | AM24: =MIN(X24,Z24) -> 213 | AO24: Lubero | AQ24: 0 | AR24: 0 | AS24: 0 | AT24: 0 | AY24: 0 | AZ24: 0
A25: Nord Kivu | B25: Butembo | C25: Alimbongo | D25: Ndoluma | E25: 12794 | F25: =IFERROR(E25*3.49%,"") -> 446.5106 | G25: =IFERROR(E25*4%,"") -> 511.76 | H25: =IFERROR((F25/12)*$C$1,"") -> 372.09217 | I25: =IFERROR((G25/12)*$C$1,"") -> 426.46667 | J25: 311 | K25: 139 | L25: 370 | M25: 363 | N25: 370 | O25: 351 | P25: 361 | Q25: 370 | R25: 333 | S25: 325 | T25: 333 | U25: 370 | V25: 361 | W25: 368 | X25: 450 | Y25: 145 | Z25: 368 | AA25: 370 | AB25: 180 | AC25: 103 | AD25: 57 | AE25: 59 | AF25: 58 | AG25: 51 | AH25: =SUM(Tableau2[[#This Row],[Td 2]:[Td 5]]) -> 225 | AI25: 58.3 | AJ25: 100 | AK25: =IFERROR(IF(H25-O25<0,0,H25-O25),0) -> 21.092167 | AL25: =IFERROR(IF(O25-X25<0,0,O25-X25),0) -> 0 | AM25: =MIN(X25,Z25) -> 368 | AO25: Mabalako | AQ25: 0.125 | AR25: 0.5 | AS25: 1 | AT25: 0 | AU25: 1 | AV25: 0.5 | AW25: 0.5 | AY25: 0 | AZ25: 0.44375
A26: Nord Kivu | B26: Butembo | C26: Alimbongo | D26: Ngekeni | E26: 7048 | F26: =IFERROR(E26*3.49%,"") -> 245.9752 | G26: =IFERROR(E26*4%,"") -> 281.92 | H26: =IFERROR((F26/12)*$C$1,"") -> 204.97933 | I26: =IFERROR((G26/12)*$C$1,"") -> 234.93333 | J26: 295 | K26: 192 | L26: 311 | M26: 212 | N26: 221 | O26: 261 | P26: 212 | Q26: 221 | R26: 261 | S26: 212 | T26: 221 | U26: 244 | V26: 203 | W26: 212 | X26: 197 | Y26: 116 | Z26: 197 | AA26: 221 | AB26: 100 | AC26: 76 | AD26: 76 | AE26: 84 | AF26: 52 | AG26: 21 | AH26: =SUM(Tableau2[[#This Row],[Td 2]:[Td 5]]) -> 233 | AI26: 58.3 | AJ26: 100 | AK26: =IFERROR(IF(H26-O26<0,0,H26-O26),0) -> 0 | AL26: =IFERROR(IF(O26-X26<0,0,O26-X26),0) -> 64 | AM26: =MIN(X26,Z26) -> 197 | AO26: Manguredjipa | AQ26: 0.5 | AR26: 1 | AS26: 1 | AT26: 0.6 | AU26: 0.5 | AV26: 1 | AW26: 0.2 | AY26: 0 | AZ26: 0.65
A27: Nord Kivu | B27: Butembo | C27: Alimbongo | D27: Taliha | E27: 11191 | F27: =IFERROR(E27*3.49%,"") -> 390.5659 | G27: =IFERROR(E27*4%,"") -> 447.64 | H27: =IFERROR((F27/12)*$C$1,"") -> 325.47158 | I27: =IFERROR((G27/12)*$C$1,"") -> 373.03333 | J27: 316 | K27: 146 | L27: 338 | M27: 299 | N27: 281 | O27: 294 | P27: 277 | Q27: 253 | R27: 305 | S27: 269 | T27: 253 | U27: 374 | V27: 333 | W27: 313 | X27: 334 | Y27: 75 | Z27: 319 | AA27: 244 | AB27: 88 | AC27: 255 | AD27: 195 | AE27: 90 | AF27: 39 | AG27: 68 | AH27: =SUM(Tableau2[[#This Row],[Td 2]:[Td 5]]) -> 392 | AI27: 58.3 | AJ27: 100 | AK27: =IFERROR(IF(H27-O27<0,0,H27-O27),0) -> 31.471583 | AL27: =IFERROR(IF(O27-X27<0,0,O27-X27),0) -> 0 | AM27: =MIN(X27,Z27) -> 319 | AO27: Masereka | AQ27: 0.125 | AR27: 0 | AS27: 1 | AT27: 0 | AV27: 1 | AW27: 1 | AY27: 0 | AZ27: 0.25735294
A28: Nord Kivu | B28: Butembo | C28: Alimbongo | D28: Vutsorovia | E28: 12999 | F28: =IFERROR(E28*3.49%,"") -> 453.6651 | G28: =IFERROR(E28*4%,"") -> 519.96 | H28: =IFERROR((F28/12)*$C$1,"") -> 378.05425 | I28: =IFERROR((G28/12)*$C$1,"") -> 433.3 | J28: 474 | K28: 154 | L28: 330 | M28: 318 | N28: 268 | O28: 360 | P28: 346 | Q28: 304 | R28: 348 | S28: 344 | T28: 289 | U28: 355 | V28: 352 | W28: 284 | X28: 339 | Y28: 175 | Z28: 345 | AA28: 217 | AB28: 185 | AC28: 94 | AD28: 84 | AE28: 60 | AF28: 51 | AG28: 48 | AH28: =SUM(Tableau2[[#This Row],[Td 2]:[Td 5]]) -> 243 | AI28: 52.8 | AJ28: 100 | AK28: =IFERROR(IF(H28-O28<0,0,H28-O28),0) -> 18.05425 | AL28: =IFERROR(IF(O28-X28<0,0,O28-X28),0) -> 21 | AM28: =MIN(X28,Z28) -> 339 | AO28: Masisi | AQ28: 0.038461538 | AR28: 0 | AS28: 0 | AT28: 0 | AV28: 0 | AW28: 0 | AY28: 0 | AZ28: 0.0067873303
A29: Nord Kivu | B29: Goma | C29: Bambo | D29: Butare | E29: 21546 | F29: =IFERROR(E29*3.49%,"") -> 751.9554 | G29: =IFERROR(E29*4%,"") -> 861.84 | H29: =IFERROR((F29/12)*$C$1,"") -> 626.6295 | I29: =IFERROR((G29/12)*$C$1,"") -> 718.2 | J29: 643 | K29: 393 | L29: 589 | M29: 568 | N29: 555 | O29: 589 | P29: 568 | Q29: 555 | R29: 589 | S29: 568 | T29: 555 | U29: 585 | V29: 568 | W29: 555 | X29: 608 | Y29: 118 | Z29: 578 | AA29: 555 | AB29: 57 | AC29: 335 | AD29: 385 | AE29: 125 | AF29: 62 | AH29: =SUM(Tableau2[[#This Row],[Td 2]:[Td 5]]) -> 572 | AI29: 50 | AJ29: 100 | AK29: =IFERROR(IF(H29-O29<0,0,H29-O29),0) -> 37.6295 | AL29: =IFERROR(IF(O29-X29<0,0,O29-X29),0) -> 0 | AM29: =MIN(X29,Z29) -> 578 | AO29: Musienene | AQ29: 0.15 | AR29: 0 | AS29: 1 | AT29: 0.66666667 | AU29: 0.5 | AV29: 1 | AW29: 0 | AY29: 0 | AZ29: 0.3475
A30: Nord Kivu | B30: Goma | C30: Bambo | D30: CBCA Bambo | E30: 17294 | F30: =IFERROR(E30*3.49%,"") -> 603.5606 | G30: =IFERROR(E30*4%,"") -> 691.76 | H30: =IFERROR((F30/12)*$C$1,"") -> 502.96717 | I30: =IFERROR((G30/12)*$C$1,"") -> 576.46667 | J30: 1205 | K30: 685 | L30: 644 | M30: 624 | N30: 634 | O30: 644 | P30: 624 | Q30: 634 | R30: 644 | S30: 625 | T30: 634 | U30: 643 | V30: 624 | W30: 634 | X30: 634 | Y30: 182 | Z30: 634 | AA30: 634 | AB30: 280 | AC30: 390 | AD30: 324 | AE30: 285 | AF30: 228 | AG30: 198 | AH30: =SUM(Tableau2[[#This Row],[Td 2]:[Td 5]]) -> 1035 | AI30: 58.3 | AJ30: 100 | AK30: =IFERROR(IF(H30-O30<0,0,H30-O30),0) -> 0 | AL30: =IFERROR(IF(O30-X30<0,0,O30-X30),0) -> 10 | AM30: =MIN(X30,Z30) -> 634 | AO30: Mutwanga | AQ30: 0.25 | AR30: 0.66666667 | AS30: 1 | AT30: 0.6 | AU30: 0.33333333 | AV30: 0.6 | AW30: 0 | AY30: 0 | AZ30: 0.47416667
A31: Nord Kivu | B31: Goma | C31: Bambo | D31: CEBCE Bambo | E31: 15244 | F31: =IFERROR(E31*3.49%,"") -> 532.0156 | G31: =IFERROR(E31*4%,"") -> 609.76 | H31: =IFERROR((F31/12)*$C$1,"") -> 443.34633 | I31: =IFERROR((G31/12)*$C$1,"") -> 508.13333 | J31: 565 | K31: 362 | L31: 401 | M31: 371 | N31: 390 | O31: 463 | P31: 431 | Q31: 450 | R31: 463 | S31: 431 | T31: 450 | U31: 463 | V31: 395 | W31: 450 | X31: 454 | Y31: 195 | Z31: 452 | AA31: 448 | AB31: 258 | AC31: 84 | AD31: 62 | AE31: 77 | AF31: 43 | AG31: 55 | AH31: =SUM(Tableau2[[#This Row],[Td 2]:[Td 5]]) -> 237 | AI31: 58.3 | AJ31: 100 | AK31: =IFERROR(IF(H31-O31<0,0,H31-O31),0) -> 0 | AL31: =IFERROR(IF(O31-X31<0,0,O31-X31),0) -> 9 | AM31: =MIN(X31,Z31) -> 452 | AO31: Mweso | AQ31: 0.68 | AR31: 0.13333333 | AS31: 1 | AT31: 0.47058824 | AU31: 1 | AV31: 0.41176471 | AW31: 0.58823529 | AY31: 0 | AZ31: 0.50592157
A32: Nord Kivu | B32: Goma | C32: Bambo | D32: Faraja | E32: 17893 | F32: =IFERROR(E32*3.49%,"") -> 624.4657 | G32: =IFERROR(E32*4%,"") -> 715.72 | H32: =IFERROR((F32/12)*$C$1,"") -> 520.38808 | I32: =IFERROR((G32/12)*$C$1,"") -> 596.43333 | J32: 596 | K32: 313 | L32: 540 | M32: 493 | N32: 491 | O32: 595 | P32: 545 | Q32: 538 | R32: 595 | S32: 545 | T32: 538 | U32: 595 | V32: 545 | W32: 538 | X32: 542 | Y32: 505 | Z32: 494 | AA32: 538 | AB32: 328 | AC32: 85 | AD32: 38 | AE32: 57 | AF32: 32 | AG32: 48 | AH32: =SUM(Tableau2[[#This Row],[Td 2]:[Td 5]]) -> 175 | AI32: 58.3 | AJ32: 100 | AK32: =IFERROR(IF(H32-O32<0,0,H32-O32),0) -> 0 | AL32: =IFERROR(IF(O32-X32<0,0,O32-X32),0) -> 53 | AM32: =MIN(X32,Z32) -> 494 | AO32: Nyiragongo | AQ32: 0.36363636 | AR32: 0.5 | AS32: 1 | AT32: 0.5 | AV32: 1 | AW32: 0.75 | AY32: 0 | AZ32: 0.52005348
A33: Nord Kivu | B33: Goma | C33: Bambo | D33: Kabizo | E33: 21628 | F33: =IFERROR(E33*3.49%,"") -> 754.8172 | G33: =IFERROR(E33*4%,"") -> 865.12 | H33: =IFERROR((F33/12)*$C$1,"") -> 629.01433 | I33: =IFERROR((G33/12)*$C$1,"") -> 720.93333 | J33: 569 | K33: 554 | L33: 393 | M33: 375 | N33: 357 | O33: 549 | P33: 524 | Q33: 511 | R33: 549 | S33: 522 | T33: 511 | U33: 549 | V33: 524 | W33: 511 | X33: 326 | Y33: 86 | Z33: 191 | AA33: 264 | AB33: 84 | AC33: 137 | AD33: 99 | AE33: 108 | AF33: 93 | AG33: 147 | AH33: =SUM(Tableau2[[#This Row],[Td 2]:[Td 5]]) -> 447 | AI33: 58.3 | AJ33: 100 | AK33: =IFERROR(IF(H33-O33<0,0,H33-O33),0) -> 80.014333 | AL33: =IFERROR(IF(O33-X33<0,0,O33-X33),0) -> 223 | AM33: =MIN(X33,Z33) -> 191 | AO33: Oicha | AQ33: 0.18518519 | AR33: 0.33333333 | AS33: 1 | AT33: 0.2 | AU33: 0 | AV33: 0.4 | AW33: 0.6 | AY33: 0 | AZ33: 0.29111111
A34: Nord Kivu | B34: Goma | C34: Bambo | D34: Kamena | E34: 17723 | F34: =IFERROR(E34*3.49%,"") -> 618.5327 | G34: =IFERROR(E34*4%,"") -> 708.92 | H34: =IFERROR((F34/12)*$C$1,"") -> 515.44392 | I34: =IFERROR((G34/12)*$C$1,"") -> 590.76667 | J34: 514 | K34: 235 | L34: 515 | M34: 500 | N34: 521 | O34: 515 | P34: 500 | Q34: 521 | R34: 519 | S34: 500 | T34: 521 | U34: 515 | V34: 500 | W34: 521 | X34: 484 | Y34: 211 | Z34: 506 | AA34: 521 | AB34: 400 | AC34: 384 | AD34: 216 | AE34: 59 | AF34: 59 | AG34: 63 | AH34: =SUM(Tableau2[[#This Row],[Td 2]:[Td 5]]) -> 397 | AI34: 58.3 | AJ34: 100 | AK34: =IFERROR(IF(H34-O34<0,0,H34-O34),0) -> 0.44391667 | AL34: =IFERROR(IF(O34-X34<0,0,O34-X34),0) -> 31 | AM34: =MIN(X34,Z34) -> 484 | AO34: Pinga | AQ34: 0.36842105 | AR34: 0.5 | AS34: 1 | AT34: 0.42857143 | AU34: 0.85714286 | AV34: 0.85714286 | AW34: 0.14285714 | AY34: 0 | AZ34: 0.5231203
A35: Nord Kivu | B35: Goma | C35: Bambo | D35: Kirumba | E35: 19416 | F35: =IFERROR(E35*3.49%,"") -> 677.6184 | G35: =IFERROR(E35*4%,"") -> 776.64 | H35: =IFERROR((F35/12)*$C$1,"") -> 564.682 | I35: =IFERROR((G35/12)*$C$1,"") -> 647.2 | J35: 720 | K35: 479 | L35: 556 | M35: 554 | N35: 551 | O35: 556 | P35: 554 | Q35: 550 | R35: 556 | S35: 554 | T35: 551 | U35: 565 | V35: 554 | W35: 550 | X35: 537 | Y35: 553 | Z35: 537 | AA35: 551 | AB35: 258 | AC35: 248 | AD35: 225 | AE35: 193 | AF35: 143 | AG35: 142 | AH35: =SUM(Tableau2[[#This Row],[Td 2]:[Td 5]]) -> 703 | AI35: 58.3 | AJ35: 100 | AK35: =IFERROR(IF(H35-O35<0,0,H35-O35),0) -> 8.682 | AL35: =IFERROR(IF(O35-X35<0,0,O35-X35),0) -> 19 | AM35: =MIN(X35,Z35) -> 537 | AO35: Rutshuru | AQ35: 0.3125 | AR35: 0.66666667 | AS35: 1 | AT35: 1 | AV35: 0.4 | AW35: 1 | AY35: 0 | AZ35: 0.62769608
A36: Nord Kivu | B36: Goma | C36: Bambo | D36: Kishishe | E36: 16150 | F36: =IFERROR(E36*3.49%,"") -> 563.635 | G36: =IFERROR(E36*4%,"") -> 646 | H36: =IFERROR((F36/12)*$C$1,"") -> 469.69583 | I36: =IFERROR((G36/12)*$C$1,"") -> 538.33333 | J36: 445 | K36: 195 | L36: 380 | M36: 352 | N36: 362 | O36: 380 | P36: 352 | Q36: 362 | R36: 380 | S36: 362 | T36: 362 | U36: 380 | V36: 362 | W36: 362 | X36: 399 | Y36: 201 | Z36: 399 | AA36: 362 | AB36: 284 | AC36: 100 | AD36: 88 | AE36: 22 | AF36: 24 | AG36: 59 | AH36: =SUM(Tableau2[[#This Row],[Td 2]:[Td 5]]) -> 193 | AI36: 58.3 | AJ36: 100 | AK36: =IFERROR(IF(H36-O36<0,0,H36-O36),0) -> 89.695833 | AL36: =IFERROR(IF(O36-X36<0,0,O36-X36),0) -> 0 | AM36: =MIN(X36,Z36) -> 399 | AO36: Rwanguba | AQ36: 0.66666667 | AR36: 0.875 | AS36: 0.875 | AT36: 0.28571429 | AU36: 1 | AV36: 0.57142857 | AW36: 0.64285714 | AY36: 0 | AZ36: 0.65982143
A37: Nord Kivu | B37: Goma | C37: Bambo | D37: Marangara | E37: 6986 | F37: =IFERROR(E37*3.49%,"") -> 243.8114 | G37: =IFERROR(E37*4%,"") -> 279.44 | H37: =IFERROR((F37/12)*$C$1,"") -> 203.17617 | I37: =IFERROR((G37/12)*$C$1,"") -> 232.86667 | J37: 224 | K37: 224 | L37: 191 | M37: 168 | N37: 176 | O37: 194 | P37: 168 | Q37: 176 | R37: 184 | S37: 168 | T37: 176 | U37: 196 | V37: 168 | W37: 176 | X37: 182 | Y37: 41 | Z37: 182 | AA37: 176 | AB37: 40 | AC37: 128 | AD37: 84 | AE37: 42 | AF37: 7 | AH37: =SUM(Tableau2[[#This Row],[Td 2]:[Td 5]]) -> 133 | AI37: 58.3 | AJ37: 100 | AK37: =IFERROR(IF(H37-O37<0,0,H37-O37),0) -> 9.1761667 | AL37: =IFERROR(IF(O37-X37<0,0,O37-X37),0) -> 12 | AM37: =MIN(X37,Z37) -> 182 | AO37: Vuhovi | AQ37: 0 | AR37: 0 | AS37: 0 | AT37: 0 | AY37: 0 | AZ37: 0
A38: Nord Kivu | B38: Goma | C38: Bambo | D38: Mushababwe | E38: 14728 | F38: =IFERROR(E38*3.49%,"") -> 514.0072 | G38: =IFERROR(E38*4%,"") -> 589.12 | H38: =IFERROR((F38/12)*$C$1,"") -> 428.33933 | I38: =IFERROR((G38/12)*$C$1,"") -> 490.93333 | J38: 431 | K38: 234 | L38: 365 | M38: 320 | N38: 349 | O38: 365 | P38: 320 | Q38: 349 | R38: 365 | S38: 320 | T38: 349 | U38: 365 | V38: 320 | W38: 349 | X38: 382 | Y38: 94 | Z38: 382 | AA38: 349 | AB38: 5 | AC38: 268 | AD38: 179 | AE38: 73 | AF38: 47 | AG38: 30 | AH38: =SUM(Tableau2[[#This Row],[Td 2]:[Td 5]]) -> 329 | AI38: 58.3 | AJ38: 100 | AK38: =IFERROR(IF(H38-O38<0,0,H38-O38),0) -> 63.339333 | AL38: =IFERROR(IF(O38-X38<0,0,O38-X38),0) -> 0 | AM38: =MIN(X38,Z38) -> 382 | AO38: Walikale | AQ38: 0 | AR38: 0 | AS38: 0 | AT38: 0 | AY38: 0 | AZ38: 0
A39: Nord Kivu | B39: Goma | C39: Bambo | D39: Rebero | E39: 8215 | F39: =IFERROR(E39*3.49%,"") -> 286.7035 | G39: =IFERROR(E39*4%,"") -> 328.6 | H39: =IFERROR((F39/12)*$C$1,"") -> 238.91958 | I39: =IFERROR((G39/12)*$C$1,"") -> 273.83333 | J39: 441 | K39: 383 | L39: 250 | M39: 214 | N39: 209 | O39: 250 | P39: 214 | Q39: 209 | R39: 250 | S39: 214 | T39: 209 | U39: 250 | V39: 214 | W39: 209 | X39: 298 | Y39: 93 | Z39: 298 | AA39: 223 | AB39: 117 | AC39: 93 | AD39: 55 | AE39: 48 | AF39: 28 | AG39: 27 | AH39: =SUM(Tableau2[[#This Row],[Td 2]:[Td 5]]) -> 158 | AI39: 58.3 | AJ39: 100 | AK39: =IFERROR(IF(H39-O39<0,0,H39-O39),0) -> 0 | AL39: =IFERROR(IF(O39-X39<0,0,O39-X39),0) -> 0 | AM39: =MIN(X39,Z39) -> 298
A40: Nord Kivu | B40: Goma | C40: Bambo | D40: Rushovu | E40: 13391 | F40: =IFERROR(E40*3.49%,"") -> 467.3459 | G40: =IFERROR(E40*4%,"") -> 535.64 | H40: =IFERROR((F40/12)*$C$1,"") -> 389.45492 | I40: =IFERROR((G40/12)*$C$1,"") -> 446.36667 | J40: 578 | K40: 259 | L40: 525 | M40: 459 | N40: 515 | O40: 517 | P40: 459 | Q40: 515 | R40: 516 | S40: 459 | T40: 515 | U40: 525 | V40: 459 | W40: 515 | X40: 507 | Y40: 181 | Z40: 356 | AA40: 515 | AB40: 199 | AC40: 485 | AD40: 318 | AE40: 184 | AF40: 30 | AG40: 13 | AH40: =SUM(Tableau2[[#This Row],[Td 2]:[Td 5]]) -> 545 | AI40: 58.3 | AJ40: 100 | AK40: =IFERROR(IF(H40-O40<0,0,H40-O40),0) -> 0 | AL40: =IFERROR(IF(O40-X40<0,0,O40-X40),0) -> 10 | AM40: =MIN(X40,Z40) -> 356
...

Sheet ANAPEV
B3: ZS | C3: Données des Populations, Doses de Vaccins Administrées, CV | J3: Analyse des Problèmes | R3: Zone par priorité | S3: Plan de rederessement
C4: Chiffre Pop Cible | D4: Doses de vaccins administrées | G4: Couverture Vaccinale(%) | J4: EZD/Non Vaccinés(nb) | K4: ESV/sous Vaccine | L4: Taux Abandon % | N4: Type de problèmes | P4: Catégorie de Probleme | Q4: Indicateur Mashako/Score
C6: < 1an | D6: Penta 1 | E6: Penta 3 | F6: VAR | G6: Penta 1 | H6: Penta 3 | I6: VAR | J6: Penta 1 | K6: VAR | L6: Penta1-Penta3 | M6: Penta1-VAR | N6: Accèssibilité | O6: Utilisation | P6: 1,2,3,4 | R6: Priorité 1,2,3…
B7: Alimbongo | C7: =SUMIF(Data_Entry!$C$5:$C$670,B7,Data_Entry!H$5:H$670) -> 8706.6193 | D7: =SUMIF(Data_Entry!$C$5:$C$670,B7,Data_Entry!O$5:O$670) -> 8374 | E7: =SUMIF(Data_Entry!$C$5:$C$670,B7,Data_Entry!Q$5:Q$670) -> 7634 | F7: =SUMIF(Data_Entry!$C$5:$C$670,B7,Data_Entry!X$5:X$670) -> 9099 | G7: =D7/C7 -> 0.96179696 | H7: =E7/C7 -> 0.87680415 | I7: =F7/C7 -> 1.0450669 | J7: =SUMIF(Data_Entry!$C$5:$C$670,B7,Data_Entry!AK$5:AK$670) -> 1138.1323 | K7: =SUMIF(Data_Entry!$C$5:$C$670,B7,Data_Entry!AL$5:AL$670) -> 297 | L7: =IF(((D7-E7)/D7)<0,0,(D7-E7)/D7) -> 0.08836876 | M7: =IF((D7-F7)/D7<0,0,(D7-F7)/D7) -> 0 | N7: =_xlfn.IFS(G7<95%,"Mauvaise",G7>=95%,"Bonne") -> Bonne | O7: =_xlfn.IFS(L7>10%,"Mauvaise",L7<=10%,"Bonne") -> Bonne | P7: =IF(AND(L7<=10%,G7>=90%),1,IF(AND(L7<=10%,G7<90%),3,IF(AND(L7>10%,G7>=90%),2,IF(AND(L7>10%,G7<90%),4,)))) -> 1 | Q7: =VLOOKUP(B7,Data_Entry!$AO$4:$AZ$38,12,FALSE) -> 0.60952381 | R7: =_xlfn.IFS(P7=1,4,P7=2,3,P7=3,2,P7=4,1) -> 4
B8: Beni | C8: =SUMIF(Data_Entry!$C$5:$C$670,B8,Data_Entry!H$5:H$670) -> 15523.433 | D8: =SUMIF(Data_Entry!$C$5:$C$670,B8,Data_Entry!O$5:O$670) -> 16095 | E8: =SUMIF(Data_Entry!$C$5:$C$670,B8,Data_Entry!Q$5:Q$670) -> 17069 | F8: =SUMIF(Data_Entry!$C$5:$C$670,B8,Data_Entry!X$5:X$670) -> 16414 | G8: =D8/C8 -> 1.0368196 | H8: =E8/C8 -> 1.0995635 | I8: =F8/C8 -> 1.0573692 | J8: =SUMIF(Data_Entry!$C$5:$C$670,B8,Data_Entry!AK$5:AK$670) -> 996.17142 | K8: =SUMIF(Data_Entry!$C$5:$C$670,B8,Data_Entry!AL$5:AL$670) -> 764 | L8: =IF(((D8-E8)/D8)<0,0,(D8-E8)/D8) -> 0 | M8: =IF((D8-F8)/D8<0,0,(D8-F8)/D8) -> 0 | N8: =_xlfn.IFS(G8<95%,"Mauvaise",G8>=95%,"Bonne") -> Bonne | O8: =_xlfn.IFS(L8>10%,"Mauvaise",L8<=10%,"Bonne") -> Bonne | P8: =IF(AND(L8<=10%,G8>=90%),1,IF(AND(L8<=10%,G8<90%),3,IF(AND(L8>10%,G8>=90%),2,IF(AND(L8>10%,G8<90%),4,)))) -> 1 | Q8: =VLOOKUP(B8,Data_Entry!$AO$4:$AZ$38,12,FALSE) -> 0 | R8: =_xlfn.IFS(P8=1,4,P8=2,3,P8=3,2,P8=4,1) -> 4
B9: Biena | C9: =SUMIF(Data_Entry!$C$5:$C$670,B9,Data_Entry!H$5:H$670) -> 4823.5872 | D9: =SUMIF(Data_Entry!$C$5:$C$670,B9,Data_Entry!O$5:O$670) -> 4101 | E9: =SUMIF(Data_Entry!$C$5:$C$670,B9,Data_Entry!Q$5:Q$670) -> 3610 | F9: =SUMIF(Data_Entry!$C$5:$C$670,B9,Data_Entry!X$5:X$670) -> 4046 | G9: =D9/C9 -> 0.85019714 | H9: =E9/C9 -> 0.74840567 | I9: =F9/C9 -> 0.83879483 | J9: =SUMIF(Data_Entry!$C$5:$C$670,B9,Data_Entry!AK$5:AK$670) -> 864.008 | K9: =SUMIF(Data_Entry!$C$5:$C$670,B9,Data_Entry!AL$5:AL$670) -> 268 | L9: =IF(((D9-E9)/D9)<0,0,(D9-E9)/D9) -> 0.1197269 | M9: =IF((D9-F9)/D9<0,0,(D9-F9)/D9) -> 0.013411363 | N9: =_xlfn.IFS(G9<95%,"Mauvaise",G9>=95%,"Bonne") -> Mauvaise | O9: =_xlfn.IFS(L9>10%,"Mauvaise",L9<=10%,"Bonne") -> Mauvaise | P9: =IF(AND(L9<=10%,G9>=90%),1,IF(AND(L9<=10%,G9<90%),3,IF(AND(L9>10%,G9>=90%),2,IF(AND(L9>10%,G9<90%),4,)))) -> 4 | Q9: =VLOOKUP(B9,Data_Entry!$AO$4:$AZ$38,12,FALSE) -> 0.52765152 | R9: =_xlfn.IFS(P9=1,4,P9=2,3,P9=3,2,P9=4,1) -> 1
B10: Butembo | C10: =SUMIF(Data_Entry!$C$5:$C$670,B10,Data_Entry!H$5:H$670) -> 7809.7475 | D10: =SUMIF(Data_Entry!$C$5:$C$670,B10,Data_Entry!O$5:O$670) -> 6721 | E10: =SUMIF(Data_Entry!$C$5:$C$670,B10,Data_Entry!Q$5:Q$670) -> 6097 | F10: =SUMIF(Data_Entry!$C$5:$C$670,B10,Data_Entry!X$5:X$670) -> 6907 | G10: =D10/C10 -> 0.8605912 | H10: =E10/C10 -> 0.78069105 | I10: =F10/C10 -> 0.88440759 | J10: =SUMIF(Data_Entry!$C$5:$C$670,B10,Data_Entry!AK$5:AK$670) -> 1251.2746 | K10: =SUMIF(Data_Entry!$C$5:$C$670,B10,Data_Entry!AL$5:AL$670) -> 256 | L10: =IF(((D10-E10)/D10)<0,0,(D10-E10)/D10) -> 0.092843327 | M10: =IF((D10-F10)/D10<0,0,(D10-F10)/D10) -> 0 | N10: =_xlfn.IFS(G10<95%,"Mauvaise",G10>=95%,"Bonne") -> Mauvaise | O10: =_xlfn.IFS(L10>10%,"Mauvaise",L10<=10%,"Bonne") -> Bonne | P10: =IF(AND(L10<=10%,G10>=90%),1,IF(AND(L10<=10%,G10<90%),3,IF(AND(L10>10%,G10>=90%),2,IF(AND(L10>10%,G10<90%),4,)))) -> 3 | Q10: =VLOOKUP(B10,Data_Entry!$AO$4:$AZ$38,12,FALSE) -> 0.66696429 | R10: =_xlfn.IFS(P10=1,4,P10=2,3,P10=3,2,P10=4,1) -> 2
B11: Kalunguta | C11: =SUMIF(Data_Entry!$C$5:$C$670,B11,Data_Entry!H$5:H$670) -> 6941.4937 | D11: =SUMIF(Data_Entry!$C$5:$C$670,B11,Data_Entry!O$5:O$670) -> 6554 | E11: =SUMIF(Data_Entry!$C$5:$C$670,B11,Data_Entry!Q$5:Q$670) -> 6444 | F11: =SUMIF(Data_Entry!$C$5:$C$670,B11,Data_Entry!X$5:X$670) -> 6698 | G11: =D11/C11 -> 0.94417719 | H11: =E11/C11 -> 0.92833046 | I11: =F11/C11 -> 0.96492201 | J11: =SUMIF(Data_Entry!$C$5:$C$670,B11,Data_Entry!AK$5:AK$670) -> 948.61392 | K11: =SUMIF(Data_Entry!$C$5:$C$670,B11,Data_Entry!AL$5:AL$670) -> 507 | L11: =IF(((D11-E11)/D11)<0,0,(D11-E11)/D11) -> 0.016783644 | M11: =IF((D11-F11)/D11<0,0,(D11-F11)/D11) -> 0 | N11: =_xlfn.IFS(G11<95%,"Mauvaise",G11>=95%,"Bonne") -> Mauvaise | O11: =_xlfn.IFS(L11>10%,"Mauvaise",L11<=10%,"Bonne") -> Bonne | P11: =IF(AND(L11<=10%,G11>=90%),1,IF(AND(L11<=10%,G11<90%),3,IF(AND(L11>10%,G11>=90%),2,IF(AND(L11>10%,G11<90%),4,)))) -> 1 | Q11: =VLOOKUP(B11,Data_Entry!$AO$4:$AZ$38,12,FALSE) -> 0.6 | R11: =_xlfn.IFS(P11=1,4,P11=2,3,P11=3,2,P11=4,1) -> 4
B12: Kamango | C12: =SUMIF(Data_Entry!$C$5:$C$670,B12,Data_Entry!H$5:H$670) -> 4277.6058 | D12: =SUMIF(Data_Entry!$C$5:$C$670,B12,Data_Entry!O$5:O$670) -> 5054 | E12: =SUMIF(Data_Entry!$C$5:$C$670,B12,Data_Entry!Q$5:Q$670) -> 4601 | F12: =SUMIF(Data_Entry!$C$5:$C$670,B12,Data_Entry!X$5:X$670) -> 4687 | G12: =D12/C12 -> 1.1815021 | H12: =E12/C12 -> 1.0756017 | I12: =F12/C12 -> 1.0957064 | J12: =SUMIF(Data_Entry!$C$5:$C$670,B12,Data_Entry!AK$5:AK$670) -> 265.77392 | K12: =SUMIF(Data_Entry!$C$5:$C$670,B12,Data_Entry!AL$5:AL$670) -> 740 | L12: =IF(((D12-E12)/D12)<0,0,(D12-E12)/D12) -> 0.089631975 | M12: =IF((D12-F12)/D12<0,0,(D12-F12)/D12) -> 0.07261575 | N12: =_xlfn.IFS(G12<95%,"Mauvaise",G12>=95%,"Bonne") -> Bonne | O12: =_xlfn.IFS(L12>10%,"Mauvaise",L12<=10%,"Bonne") -> Bonne | P12: =IF(AND(L12<=10%,G12>=90%),1,IF(AND(L12<=10%,G12<90%),3,IF(AND(L12>10%,G12>=90%),2,IF(AND(L12>10%,G12<90%),4,)))) -> 1 | Q12: =VLOOKUP(B12,Data_Entry!$AO$4:$AZ$38,12,FALSE) -> 0.27142857 | R12: =_xlfn.IFS(P12=1,4,P12=2,3,P12=3,2,P12=4,1) -> 4
B13: Katwa | C13: =SUMIF(Data_Entry!$C$5:$C$670,B13,Data_Entry!H$5:H$670) -> 16083.112 | D13: =SUMIF(Data_Entry!$C$5:$C$670,B13,Data_Entry!O$5:O$670) -> 17113 | E13: =SUMIF(Data_Entry!$C$5:$C$670,B13,Data_Entry!Q$5:Q$670) -> 17326 | F13: =SUMIF(Data_Entry!$C$5:$C$670,B13,Data_Entry!X$5:X$670) -> 17120 | G13: =D13/C13 -> 1.0640353 | H13: =E13/C13 -> 1.077279 | I13: =F13/C13 -> 1.0644706 | J13: =SUMIF(Data_Entry!$C$5:$C$670,B13,Data_Entry!AK$5:AK$670) -> 835.01692 | K13: =SUMIF(Data_Entry!$C$5:$C$670,B13,Data_Entry!AL$5:AL$670) -> 928 | L13: =IF(((D13-E13)/D13)<0,0,(D13-E13)/D13) -> 0 | M13: =IF((D13-F13)/D13<0,0,(D13-F13)/D13) -> 0 | N13: =_xlfn.IFS(G13<95%,"Mauvaise",G13>=95%,"Bonne") -> Bonne | O13: =_xlfn.IFS(L13>10%,"Mauvaise",L13<=10%,"Bonne") -> Bonne | P13: =IF(AND(L13<=10%,G13>=90%),1,IF(AND(L13<=10%,G13<90%),3,IF(AND(L13>10%,G13>=90%),2,IF(AND(L13>10%,G13<90%),4,)))) -> 1 | Q13: =VLOOKUP(B13,Data_Entry!$AO$4:$AZ$38,12,FALSE) -> 0.61144231 | R13: =_xlfn.IFS(P13=1,4,P13=2,3,P13=3,2,P13=4,1) -> 4
B14: Kayna | C14: =SUMIF(Data_Entry!$C$5:$C$670,B14,Data_Entry!H$5:H$670) -> 13206.218 | D14: =SUMIF(Data_Entry!$C$5:$C$670,B14,Data_Entry!O$5:O$670) -> 11516 | E14: =SUMIF(Data_Entry!$C$5:$C$670,B14,Data_Entry!Q$5:Q$670) -> 10186 | F14: =SUMIF(Data_Entry!$C$5:$C$670,B14,Data_Entry!X$5:X$670) -> 12592 | G14: =D14/C14 -> 0.87201346 | H14: =E14/C14 -> 0.77130333 | I14: =F14/C14 -> 0.95349023 | J14: =SUMIF(Data_Entry!$C$5:$C$670,B14,Data_Entry!AK$5:AK$670) -> 2123.1977 | K14: =SUMIF(Data_Entry!$C$5:$C$670,B14,Data_Entry!AL$5:AL$670) -> 622 | L14: =IF(((D14-E14)/D14)<0,0,(D14-E14)/D14) -> 0.11549149 | M14: =IF((D14-F14)/D14<0,0,(D14-F14)/D14) -> 0 | N14: =_xlfn.IFS(G14<95%,"Mauvaise",G14>=95%,"Bonne") -> Mauvaise | O14: =_xlfn.IFS(L14>10%,"Mauvaise",L14<=10%,"Bonne") -> Mauvaise | P14: =IF(AND(L14<=10%,G14>=90%),1,IF(AND(L14<=10%,G14<90%),3,IF(AND(L14>10%,G14>=90%),2,IF(AND(L14>10%,G14<90%),4,)))) -> 4 | Q14: =VLOOKUP(B14,Data_Entry!$AO$4:$AZ$38,12,FALSE) -> 0.24296675 | R14: =_xlfn.IFS(P14=1,4,P14=2,3,P14=3,2,P14=4,1) -> 1
B15: Kyondo | C15: =SUMIF(Data_Entry!$C$5:$C$670,B15,Data_Entry!H$5:H$670) -> 6749.4855 | D15: =SUMIF(Data_Entry!$C$5:$C$670,B15,Data_Entry!O$5:O$670) -> 6233 | E15: =SUMIF(Data_Entry!$C$5:$C$670,B15,Data_Entry!Q$5:Q$670) -> 6105 | F15: =SUMIF(Data_Entry!$C$5:$C$670,B15,Data_Entry!X$5:X$670) -> 6394 | G15: =D15/C15 -> 0.9234778 | H15: =E15/C15 -> 0.90451339 | I15: =F15/C15 -> 0.94733147 | J15: =SUMIF(Data_Entry!$C$5:$C$670,B15,Data_Entry!AK$5:AK$670) -> 665.53317 | K15: =SUMIF(Data_Entry!$C$5:$C$670,B15,Data_Entry!AL$5:AL$670) -> 273 | L15: =IF(((D15-E15)/D15)<0,0,(D15-E15)/D15) -> 0.020535858 | M15: =IF((D15-F15)/D15<0,0,(D15-F15)/D15) -> 0 | N15: =_xlfn.IFS(G15<95%,"Mauvaise",G15>=95%,"Bonne") -> Mauvaise | O15: =_xlfn.IFS(L15>10%,"Mauvaise",L15<=10%,"Bonne") -> Bonne | P15: =IF(AND(L15<=10%,G15>=90%),1,IF(AND(L15<=10%,G15<90%),3,IF(AND(L15>10%,G15>=90%),2,IF(AND(L15>10%,G15<90%),4,)))) -> 1 | Q15: =VLOOKUP(B15,Data_Entry!$AO$4:$AZ$38,12,FALSE) -> 0.65393375 | R15: =_xlfn.IFS(P15=1,4,P15=2,3,P15=3,2,P15=4,1) -> 4
B16: Lubero | C16: =SUMIF(Data_Entry!$C$5:$C$670,B16,Data_Entry!H$5:H$670) -> 10515.544 | D16: =SUMIF(Data_Entry!$C$5:$C$670,B16,Data_Entry!O$5:O$670) -> 10234 | E16: =SUMIF(Data_Entry!$C$5:$C$670,B16,Data_Entry!Q$5:Q$670) -> 10087 | F16: =SUMIF(Data_Entry!$C$5:$C$670,B16,Data_Entry!X$5:X$670) -> 9697 | G16: =D16/C16 -> 0.97322588 | H16: =E16/C16 -> 0.95924657 | I16: =F16/C16 -> 0.92215862 | J16: =SUMIF(Data_Entry!$C$5:$C$670,B16,Data_Entry!AK$5:AK$670) -> 469.80233 | K16: =SUMIF(Data_Entry!$C$5:$C$670,B16,Data_Entry!AL$5:AL$670) -> 670 | L16: =IF(((D16-E16)/D16)<0,0,(D16-E16)/D16) -> 0.014363885 | M16: =IF((D16-F16)/D16<0,0,(D16-F16)/D16) -> 0.052472152 | N16: =_xlfn.IFS(G16<95%,"Mauvaise",G16>=95%,"Bonne") -> Bonne | O16: =_xlfn.IFS(L16>10%,"Mauvaise",L16<=10%,"Bonne") -> Bonne | P16: =IF(AND(L16<=10%,G16>=90%),1,IF(AND(L16<=10%,G16<90%),3,IF(AND(L16>10%,G16>=90%),2,IF(AND(L16>10%,G16<90%),4,)))) -> 1 | Q16: =VLOOKUP(B16,Data_Entry!$AO$4:$AZ$38,12,FALSE) -> 0 | R16: =_xlfn.IFS(P16=1,4,P16=2,3,P16=3,2,P16=4,1) -> 4
B17: Mabalako | C17: =SUMIF(Data_Entry!$C$5:$C$670,B17,Data_Entry!H$5:H$670) -> 7118.4657 | D17: =SUMIF(Data_Entry!$C$5:$C$670,B17,Data_Entry!O$5:O$670) -> 6267 | E17: =SUMIF(Data_Entry!$C$5:$C$670,B17,Data_Entry!Q$5:Q$670) -> 6115 | F17: =SUMIF(Data_Entry!$C$5:$C$670,B17,Data_Entry!X$5:X$670) -> 6562 | G17: =D17/C17 -> 0.88038634 | H17: =E17/C17 -> 0.85903342 | I17: =F17/C17 -> 0.92182785 | J17: =SUMIF(Data_Entry!$C$5:$C$670,B17,Data_Entry!AK$5:AK$670) -> 1125.3214 | K17: =SUMIF(Data_Entry!$C$5:$C$670,B17,Data_Entry!AL$5:AL$670) -> 204 | L17: =IF(((D17-E17)/D17)<0,0,(D17-E17)/D17) -> 0.024254029 | M17: =IF((D17-F17)/D17<0,0,(D17-F17)/D17) -> 0 | N17: =_xlfn.IFS(G17<95%,"Mauvaise",G17>=95%,"Bonne") -> Mauvaise | O17: =_xlfn.IFS(L17>10%,"Mauvaise",L17<=10%,"Bonne") -> Bonne | P17: =IF(AND(L17<=10%,G17>=90%),1,IF(AND(L17<=10%,G17<90%),3,IF(AND(L17>10%,G17>=90%),2,IF(AND(L17>10%,G17<90%),4,)))) -> 3 | Q17: =VLOOKUP(B17,Data_Entry!$AO$4:$AZ$38,12,FALSE) -> 0.44375 | R17: =_xlfn.IFS(P17=1,4,P17=2,3,P17=3,2,P17=4,1) -> 2
B18: Manguredjipa | C18: =SUMIF(Data_Entry!$C$5:$C$670,B18,Data_Entry!H$5:H$670) -> 2840.7146 | D18: =SUMIF(Data_Entry!$C$5:$C$670,B18,Data_Entry!O$5:O$670) -> 2850 | E18: =SUMIF(Data_Entry!$C$5:$C$670,B18,Data_Entry!Q$5:Q$670) -> 2318 | F18: =SUMIF(Data_Entry!$C$5:$C$670,B18,Data_Entry!X$5:X$670) -> 2384 | G18: =D18/C18 -> 1.0032687 | H18: =E18/C18 -> 0.81599187 | I18: =F18/C18 -> 0.83922546 | J18: =SUMIF(Data_Entry!$C$5:$C$670,B18,Data_Entry!AK$5:AK$670) -> 375.18675 | K18: =SUMIF(Data_Entry!$C$5:$C$670,B18,Data_Entry!AL$5:AL$670) -> 522 | L18: =IF(((D18-E18)/D18)<0,0,(D18-E18)/D18) -> 0.18666667 | M18: =IF((D18-F18)/D18<0,0,(D18-F18)/D18) -> 0.16350877 | N18: =_xlfn.IFS(G18<95%,"Mauvaise",G18>=95%,"Bonne") -> Bonne | O18: =_xlfn.IFS(L18>10%,"Mauvaise",L18<=10%,"Bonne") -> Mauvaise | P18: =IF(AND(L18<=10%,G18>=90%),1,IF(AND(L18<=10%,G18<90%),3,IF(AND(L18>10%,G18>=90%),2,IF(AND(L18>10%,G18<90%),4,)))) -> 2 | Q18: =VLOOKUP(B18,Data_Entry!$AO$4:$AZ$38,12,FALSE) -> 0.65 | R18: =_xlfn.IFS(P18=1,4,P18=2,3,P18=3,2,P18=4,1) -> 3
... B23: Vuhovi | C23: =SUMIF(Data_Entry!$C$5:$C$670,B23,Data_Entry!H$5:H$670) -> 4409.7023 | D23: =SUMIF(Data_Entry!$C$5:$C$670,B23,Data_Entry!O$5:O$670) -> 3997 | E23: =SUMIF(Data_Entry!$C$5:$C$670,B23,Data_Entry!Q$5:Q$670) -> 3922 | F23: =SUMIF(Data_Entry!$C$5:$C$670,B23,Data_Entry!X$5:X$670) -> 4279 | G23: =D23/C23 -> 0.9064104 | H23: =E23/C23 -> 0.88940245 | I23: =F23/C23 -> 0.9703603 | J23: =SUMIF(Data_Entry!$C$5:$C$670,B23,Data_Entry!AK$5:AK$670) -> 726.15125 | K23: =SUMIF(Data_Entry!$C$5:$C$670,B23,Data_Entry!AL$5:AL$670) -> 83 | L23: =IF(((D23-E23)/D23)<0,0,(D23-E23)/D23) -> 0.018764073 | M23: =IF((D23-F23)/D23<0,0,(D23-F23)/D23) -> 0 | N23: =_xlfn.IFS(G23<95%,"Mauvaise",G23>=95%,"Bonne") -> Mauvaise | O23: =_xlfn.IFS(L23>10%,"Mauvaise",L23<=10%,"Bonne") -> Bonne | P23: =IF(AND(L23<=10%,G23>=90%),1,IF(AND(L23<=10%,G23<90%),3,IF(AND(L23>10%,G23>=90%),2,IF(AND(L23>10%,G23<90%),4,)))) -> 1 | Q23: =VLOOKUP(B23,Data_Entry!$AO$4:$AZ$38,12,FALSE) -> 0 | R23: =_xlfn.IFS(P23=1,4,P23=2,3,P23=3,2,P23=4,1) -> 4
B24: ANT. BUTEMBO | C24: =SUM(C7:C23) -> 144662.07 | D24: =SUM(D7:D23) -> 136437 | E24: =SUM(E7:E23) -> 131124 | F24: =SUM(F7:F23) -> 136839 | G24: =D24/C24 -> 0.94314287 | H24: =E24/C24 -> 0.90641589 | I24: =F24/C24 -> 0.94592176 | J24: =SUM(J7:J23) -> 16943.997 | K24: =SUM(K7:K23) -> 8555 | L24: =IF(((D24-E24)/D24)<0,0,(D24-E24)/D24) -> 0.03894105 | M24: =IF((D24-F24)/D24<0,0,(D24-F24)/D24) -> 0 | N24: =_xlfn.IFS(G24<95%,"Mauvaise",G24>=95%,"Bonne") -> Mauvaise | O24: =_xlfn.IFS(L24>10%,"Mauvaise",L24<=10%,"Bonne") -> Bonne | P24: =IF(AND(L24<=10%,G24>=90%),1,IF(AND(L24<=10%,G24<90%),3,IF(AND(L24>10%,G24>=90%),2,IF(AND(L24>10%,G24<90%),4,)))) -> 1
B25: Bambo | C25: =SUMIF(Data_Entry!$C$5:$C$670,B25,Data_Entry!H$5:H$670) -> 6193.3249 | D25: =SUMIF(Data_Entry!$C$5:$C$670,B25,Data_Entry!O$5:O$670) -> 6274 | E25: =SUMIF(Data_Entry!$C$5:$C$670,B25,Data_Entry!Q$5:Q$670) -> 6014 | F25: =SUMIF(Data_Entry!$C$5:$C$670,B25,Data_Entry!X$5:X$670) -> 6062 | G25: =D25/C25 -> 1.0130261 | H25: =E25/C25 -> 0.97104545 | I25: =F25/C25 -> 0.97879573 | J25: =SUMIF(Data_Entry!$C$5:$C$670,B25,Data_Entry!AK$5:AK$670) -> 293.24883 | K25: =SUMIF(Data_Entry!$C$5:$C$670,B25,Data_Entry!AL$5:AL$670) -> 367 | L25: =IF(((D25-E25)/D25)<0,0,(D25-E25)/D25) -> 0.041440867 | M25: =IF((D25-F25)/D25<0,0,(D25-F25)/D25) -> 0.033790245 | N25: =_xlfn.IFS(G25<95%,"Mauvaise",G25>=95%,"Bonne") -> Bonne | O25: =_xlfn.IFS(L25>10%,"Mauvaise",L25<=10%,"Bonne") -> Bonne | P25: =IF(AND(L25<=10%,G25>=90%),1,IF(AND(L25<=10%,G25<90%),3,IF(AND(L25>10%,G25>=90%),2,IF(AND(L25>10%,G25<90%),4,)))) -> 1 | Q25: =VLOOKUP(B25,Data_Entry!$AO$4:$AZ$38,12,FALSE) -> 0.77596154 | R25: =_xlfn.IFS(P25=1,4,P25=2,3,P25=3,2,P25=4,1) -> 4
B26: Binza | C26: =SUMIF(Data_Entry!$C$5:$C$670,B26,Data_Entry!H$5:H$670) -> 6399.3512 | D26: =SUMIF(Data_Entry!$C$5:$C$670,B26,Data_Entry!O$5:O$670) -> 6705 | E26: =SUMIF(Data_Entry!$C$5:$C$670,B26,Data_Entry!Q$5:Q$670) -> 6735 | F26: =SUMIF(Data_Entry!$C$5:$C$670,B26,Data_Entry!X$5:X$670) -> 6664 | G26: =D26/C26 -> 1.0477625 | H26: =E26/C26 -> 1.0524504 | I26: =F26/C26 -> 1.0413556 | J26: =SUMIF(Data_Entry!$C$5:$C$670,B26,Data_Entry!AK$5:AK$670) -> 213.48783 | K26: =SUMIF(Data_Entry!$C$5:$C$670,B26,Data_Entry!AL$5:AL$670) -> 320 | L26: =IF(((D26-E26)/D26)<0,0,(D26-E26)/D26) -> 0 | M26: =IF((D26-F26)/D26<0,0,(D26-F26)/D26) -> 0.0061148397 | N26: =_xlfn.IFS(G26<95%,"Mauvaise",G26>=95%,"Bonne") -> Bonne | O26: =_xlfn.IFS(L26>10%,"Mauvaise",L26<=10%,"Bonne") -> Bonne | P26: =IF(AND(L26<=10%,G26>=90%),1,IF(AND(L26<=10%,G26<90%),3,IF(AND(L26>10%,G26>=90%),2,IF(AND(L26>10%,G26<90%),4,)))) -> 1 | Q26: =VLOOKUP(B26,Data_Entry!$AO$4:$AZ$38,12,FALSE) -> 0.6902381 | R26: =_xlfn.IFS(P26=1,4,P26=2,3,P26=3,2,P26=4,1) -> 4
B27: Birambizo | C27: =SUMIF(Data_Entry!$C$5:$C$670,B27,Data_Entry!H$5:H$670) -> 7013.6785 | D27: =SUMIF(Data_Entry!$C$5:$C$670,B27,Data_Entry!O$5:O$670) -> 7265 | E27: =SUMIF(Data_Entry!$C$5:$C$670,B27,Data_Entry!Q$5:Q$670) -> 6711 | F27: =SUMIF(Data_Entry!$C$5:$C$670,B27,Data_Entry!X$5:X$670) -> 6335 | G27: =D27/C27 -> 1.0358331 | H27: =E27/C27 -> 0.95684454 | I27: =F27/C27 -> 0.90323501 | J27: =SUMIF(Data_Entry!$C$5:$C$670,B27,Data_Entry!AK$5:AK$670) -> 178.36867 | K27: =SUMIF(Data_Entry!$C$5:$C$670,B27,Data_Entry!AL$5:AL$670) -> 1119 | L27: =IF(((D27-E27)/D27)<0,0,(D27-E27)/D27) -> 0.076256022 | M27: =IF((D27-F27)/D27<0,0,(D27-F27)/D27) -> 0.12801101 | N27: =_xlfn.IFS(G27<95%,"Mauvaise",G27>=95%,"Bonne") -> Bonne | O27: =_xlfn.IFS(L27>10%,"Mauvaise",L27<=10%,"Bonne") -> Bonne | P27: =IF(AND(L27<=10%,G27>=90%),1,IF(AND(L27<=10%,G27<90%),3,IF(AND(L27>10%,G27>=90%),2,IF(AND(L27>10%,G27<90%),4,)))) -> 1 | Q27: =VLOOKUP(B27,Data_Entry!$AO$4:$AZ$38,12,FALSE) -> 0.56607143 | R27: =_xlfn.IFS(P27=1,4,P27=2,3,P27=3,2,P27=4,1) -> 4
B28: Goma | C28: =SUMIF(Data_Entry!$C$5:$C$670,B28,Data_Entry!H$5:H$670) -> 9584.0926 | D28: =SUMIF(Data_Entry!$C$5:$C$670,B28,Data_Entry!O$5:O$670) -> 15209 | E28: =SUMIF(Data_Entry!$C$5:$C$670,B28,Data_Entry!Q$5:Q$670) -> 14284 | F28: =SUMIF(Data_Entry!$C$5:$C$670,B28,Data_Entry!X$5:X$670) -> 13329 | G28: =D28/C28 -> 1.5869004 | H28: =E28/C28 -> 1.4903863 | I28: =F28/C28 -> 1.390742 | J28: =SUMIF(Data_Entry!$C$5:$C$670,B28,Data_Entry!AK$5:AK$670) -> 472.68725 | K28: =SUMIF(Data_Entry!$C$5:$C$670,B28,Data_Entry!AL$5:AL$670) -> 2190 | L28: =IF(((D28-E28)/D28)<0,0,(D28-E28)/D28) -> 0.060819252 | M28: =IF((D28-F28)/D28<0,0,(D28-F28)/D28) -> 0.12361102 | N28: =_xlfn.IFS(G28<95%,"Mauvaise",G28>=95%,"Bonne") -> Bonne | O28: =_xlfn.IFS(L28>10%,"Mauvaise",L28<=10%,"Bonne") -> Bonne | P28: =IF(AND(L28<=10%,G28>=90%),1,IF(AND(L28<=10%,G28<90%),3,IF(AND(L28>10%,G28>=90%),2,IF(AND(L28>10%,G28<90%),4,)))) -> 1 | Q28: =VLOOKUP(B28,Data_Entry!$AO$4:$AZ$38,12,FALSE) -> 0.61764706 | R28: =_xlfn.IFS(P28=1,4,P28=2,3,P28=3,2,P28=4,1) -> 4
B29: Itebero | C29: =SUMIF(Data_Entry!$C$5:$C$670,B29,Data_Entry!H$5:H$670) -> 6924.9453 | D29: =SUMIF(Data_Entry!$C$5:$C$670,B29,Data_Entry!O$5:O$670) -> 7288 | E29: =SUMIF(Data_Entry!$C$5:$C$670,B29,Data_Entry!Q$5:Q$670) -> 7278 | F29: =SUMIF(Data_Entry!$C$5:$C$670,B29,Data_Entry!X$5:X$670) -> 6738 | G29: =D29/C29 -> 1.0524271 | H29: =E29/C29 -> 1.050983 | I29: =F29/C29 -> 0.97300408 | J29: =SUMIF(Data_Entry!$C$5:$C$670,B29,Data_Entry!AK$5:AK$670) -> 278.59108 | K29: =SUMIF(Data_Entry!$C$5:$C$670,B29,Data_Entry!AL$5:AL$670) -> 641 | L29: =IF(((D29-E29)/D29)<0,0,(D29-E29)/D29) -> 0.0013721186 | M29: =IF((D29-F29)/D29<0,0,(D29-F29)/D29) -> 0.07546652 | N29: =_xlfn.IFS(G29<95%,"Mauvaise",G29>=95%,"Bonne") -> Bonne | O29: =_xlfn.IFS(L29>10%,"Mauvaise",L29<=10%,"Bonne") -> Bonne | P29: =IF(AND(L29<=10%,G29>=90%),1,IF(AND(L29<=10%,G29<90%),3,IF(AND(L29>10%,G29>=90%),2,IF(AND(L29>10%,G29<90%),4,)))) -> 1 | Q29: =VLOOKUP(B29,Data_Entry!$AO$4:$AZ$38,12,FALSE) -> 0.47647059 | R29: =_xlfn.IFS(P29=1,4,P29=2,3,P29=3,2,P29=4,1) -> 4
B30: Karisimbi | C30: =SUMIF(Data_Entry!$C$5:$C$670,B30,Data_Entry!H$5:H$670) -> 19347.804 | D30: =SUMIF(Data_Entry!$C$5:$C$670,B30,Data_Entry!O$5:O$670) -> 22683 | E30: =SUMIF(Data_Entry!$C$5:$C$670,B30,Data_Entry!Q$5:Q$670) -> 20007 | F30: =SUMIF(Data_Entry!$C$5:$C$670,B30,Data_Entry!X$5:X$670) -> 22618 | G30: =D30/C30 -> 1.1723811 | H30: =E30/C30 -> 1.0340709 | I30: =F30/C30 -> 1.1690216 | J30: =SUMIF(Data_Entry!$C$5:$C$670,B30,Data_Entry!AK$5:AK$670) -> 3803.8786 | K30: =SUMIF(Data_Entry!$C$5:$C$670,B30,Data_Entry!AL$5:AL$670) -> 1979 | L30: =IF(((D30-E30)/D30)<0,0,(D30-E30)/D30) -> 0.11797381 | M30: =IF((D30-F30)/D30<0,0,(D30-F30)/D30) -> 0.0028655822 | N30: =_xlfn.IFS(G30<95%,"Mauvaise",G30>=95%,"Bonne") -> Bonne | O30: =_xlfn.IFS(L30>10%,"Mauvaise",L30<=10%,"Bonne") -> Mauvaise | P30: =IF(AND(L30<=10%,G30>=90%),1,IF(AND(L30<=10%,G30<90%),3,IF(AND(L30>10%,G30>=90%),2,IF(AND(L30>10%,G30<90%),4,)))) -> 2 | Q30: =VLOOKUP(B30,Data_Entry!$AO$4:$AZ$38,12,FALSE) -> 0 | R30: =_xlfn.IFS(P30=1,4,P30=2,3,P30=3,2,P30=4,1) -> 3
B31: Katoyi | C31: =SUMIF(Data_Entry!$C$5:$C$670,B31,Data_Entry!H$5:H$670) -> 11143.134 | D31: =SUMIF(Data_Entry!$C$5:$C$670,B31,Data_Entry!O$5:O$670) -> 12921 | E31: =SUMIF(Data_Entry!$C$5:$C$670,B31,Data_Entry!Q$5:Q$670) -> 12429 | F31: =SUMIF(Data_Entry!$C$5:$C$670,B31,Data_Entry!X$5:X$670) -> 12266 | G31: =D31/C31 -> 1.1595481 | H31: =E31/C31 -> 1.1153954 | I31: =F31/C31 -> 1.1007675 | J31: =SUMIF(Data_Entry!$C$5:$C$670,B31,Data_Entry!AK$5:AK$670) -> 29.964833 | K31: =SUMIF(Data_Entry!$C$5:$C$670,B31,Data_Entry!AL$5:AL$670) -> 1082 | L31: =IF(((D31-E31)/D31)<0,0,(D31-E31)/D31) -> 0.038077548 | M31: =IF((D31-F31)/D31<0,0,(D31-F31)/D31) -> 0.050692671 | N31: =_xlfn.IFS(G31<95%,"Mauvaise",G31>=95%,"Bonne") -> Bonne | O31: =_xlfn.IFS(L31>10%,"Mauvaise",L31<=10%,"Bonne") -> Bonne | P31: =IF(AND(L31<=10%,G31>=90%),1,IF(AND(L31<=10%,G31<90%),3,IF(AND(L31>10%,G31>=90%),2,IF(AND(L31>10%,G31<90%),4,)))) -> 1 | Q31: =VLOOKUP(B31,Data_Entry!$AO$4:$AZ$38,12,FALSE) -> 0.48421053 | R31: =_xlfn.IFS(P31=1,4,P31=2,3,P31=3,2,P31=4,1) -> 4
B32: Kibirizi | C32: =SUMIF(Data_Entry!$C$5:$C$670,B32,Data_Entry!H$5:H$670) -> 12549.662 | D32: =SUMIF(Data_Entry!$C$5:$C$670,B32,Data_Entry!O$5:O$670) -> 12959 | E32: =SUMIF(Data_Entry!$C$5:$C$670,B32,Data_Entry!Q$5:Q$670) -> 12176 | F32: =SUMIF(Data_Entry!$C$5:$C$670,B32,Data_Entry!X$5:X$670) -> 12482 | G32: =D32/C32 -> 1.0326175 | H32: =E32/C32 -> 0.97022534 | I32: =F32/C32 -> 0.99460847 | J32: =SUMIF(Data_Entry!$C$5:$C$670,B32,Data_Entry!AK$5:AK$670) -> 568.10608 | K32: =SUMIF(Data_Entry!$C$5:$C$670,B32,Data_Entry!AL$5:AL$670) -> 1032 | L32: =IF(((D32-E32)/D32)<0,0,(D32-E32)/D32) -> 0.060421329 | M32: =IF((D32-F32)/D32<0,0,(D32-F32)/D32) -> 0.036808396 | N32: =_xlfn.IFS(G32<95%,"Mauvaise",G32>=95%,"Bonne") -> Bonne | O32: =_xlfn.IFS(L32>10%,"Mauvaise",L32<=10%,"Bonne") -> Bonne | P32: =IF(AND(L32<=10%,G32>=90%),1,IF(AND(L32<=10%,G32<90%),3,IF(AND(L32>10%,G32>=90%),2,IF(AND(L32>10%,G32<90%),4,)))) -> 1 | Q32: =VLOOKUP(B32,Data_Entry!$AO$4:$AZ$38,12,FALSE) -> 0.56789216 | R32: =_xlfn.IFS(P32=1,4,P32=2,3,P32=3,2,P32=4,1) -> 4
B33: Kibua | C33: =SUMIF(Data_Entry!$C$5:$C$670,B33,Data_Entry!H$5:H$670) -> 4165.1405 | D33: =SUMIF(Data_Entry!$C$5:$C$670,B33,Data_Entry!O$5:O$670) -> 3999 | E33: =SUMIF(Data_Entry!$C$5:$C$670,B33,Data_Entry!Q$5:Q$670) -> 3759 | F33: =SUMIF(Data_Entry!$C$5:$C$670,B33,Data_Entry!X$5:X$670) -> 3616 | G33: =D33/C33 -> 0.96011167 | H33: =E33/C33 -> 0.90249056 | I33: =F33/C33 -> 0.86815799 | J33: =SUMIF(Data_Entry!$C$5:$C$670,B33,Data_Entry!AK$5:AK$670) -> 339.60133 | K33: =SUMIF(Data_Entry!$C$5:$C$670,B33,Data_Entry!AL$5:AL$670) -> 424 | L33: =IF(((D33-E33)/D33)<0,0,(D33-E33)/D33) -> 0.060015004 | M33: =IF((D33-F33)/D33<0,0,(D33-F33)/D33) -> 0.095773943 | N33: =_xlfn.IFS(G33<95%,"Mauvaise",G33>=95%,"Bonne") -> Bonne | O33: =_xlfn.IFS(L33>10%,"Mauvaise",L33<=10%,"Bonne") -> Bonne | P33: =IF(AND(L33<=10%,G33>=90%),1,IF(AND(L33<=10%,G33<90%),3,IF(AND(L33>10%,G33>=90%),2,IF(AND(L33>10%,G33<90%),4,)))) -> 1 | Q33: =VLOOKUP(B33,Data_Entry!$AO$4:$AZ$38,12,FALSE) -> 0.54035088 | R33: =_xlfn.IFS(P33=1,4,P33=2,3,P33=3,2,P33=4,1) -> 4
B34: Kirotshe | C34: =SUMIF(Data_Entry!$C$5:$C$670,B34,Data_Entry!H$5:H$670) -> 14972.013 | D34: =SUMIF(Data_Entry!$C$5:$C$670,B34,Data_Entry!O$5:O$670) -> 9340 | E34: =SUMIF(Data_Entry!$C$5:$C$670,B34,Data_Entry!Q$5:Q$670) -> 8197 | F34: =SUMIF(Data_Entry!$C$5:$C$670,B34,Data_Entry!X$5:X$670) -> 8292 | G34: =D34/C34 -> 0.62383062 | H34: =E34/C34 -> 0.54748818 | I34: =F34/C34 -> 0.55383335 | J34: =SUMIF(Data_Entry!$C$5:$C$670,B34,Data_Entry!AK$5:AK$670) -> 5762.6368 | K34: =SUMIF(Data_Entry!$C$5:$C$670,B34,Data_Entry!AL$5:AL$670) -> 1344 | L34: =IF(((D34-E34)/D34)<0,0,(D34-E34)/D34) -> 0.12237687 | M34: =IF((D34-F34)/D34<0,0,(D34-F34)/D34) -> 0.11220557 | N34: =_xlfn.IFS(G34<95%,"Mauvaise",G34>=95%,"Bonne") -> Mauvaise | O34: =_xlfn.IFS(L34>10%,"Mauvaise",L34<=10%,"Bonne") -> Mauvaise | P34: =IF(AND(L34<=10%,G34>=90%),1,IF(AND(L34<=10%,G34<90%),3,IF(AND(L34>10%,G34>=90%),2,IF(AND(L34>10%,G34<90%),4,)))) -> 4 | Q34: =VLOOKUP(B34,Data_Entry!$AO$4:$AZ$38,12,FALSE) -> 0 | R34: =_xlfn.IFS(P34=1,4,P34=2,3,P34=3,2,P34=4,1) -> 1
B35: Masisi | C35: =SUMIF(Data_Entry!$C$5:$C$670,B35,Data_Entry!H$5:H$670) -> 13289.542 | D35: =SUMIF(Data_Entry!$C$5:$C$670,B35,Data_Entry!O$5:O$670) -> 18088 | E35: =SUMIF(Data_Entry!$C$5:$C$670,B35,Data_Entry!Q$5:Q$670) -> 16374 | F35: =SUMIF(Data_Entry!$C$5:$C$670,B35,Data_Entry!X$5:X$670) -> 18696 | G35: =D35/C35 -> 1.3610702 | H35: =E35/C35 -> 1.2320966 | I35: =F35/C35 -> 1.4068205 | J35: =SUMIF(Data_Entry!$C$5:$C$670,B35,Data_Entry!AK$5:AK$670) -> 995.03467 | K35: =SUMIF(Data_Entry!$C$5:$C$670,B35,Data_Entry!AL$5:AL$670) -> 2524 | L35: =IF(((D35-E35)/D35)<0,0,(D35-E35)/D35) -> 0.094758956 | M35: =IF((D35-F35)/D35<0,0,(D35-F35)/D35) -> 0 | N35: =_xlfn.IFS(G35<95%,"Mauvaise",G35>=95%,"Bonne") -> Bonne | O35: =_xlfn.IFS(L35>10%,"Mauvaise",L35<=10%,"Bonne") -> Bonne | P35: =IF(AND(L35<=10%,G35>=90%),1,IF(AND(L35<=10%,G35<90%),3,IF(AND(L35>10%,G35>=90%),2,IF(AND(L35>10%,G35<90%),4,)))) -> 1 | Q35: =VLOOKUP(B35,Data_Entry!$AO$4:$AZ$38,12,FALSE) -> 0.0067873303 | R35: =_xlfn.IFS(P35=1,4,P35=2,3,P35=3,2,P35=4,1) -> 4
B36: Mweso | C36: =SUMIF(Data_Entry!$C$5:$C$670,B36,Data_Entry!H$5:H$670) -> 15246.414 | D36: =SUMIF(Data_Entry!$C$5:$C$670,B36,Data_Entry!O$5:O$670) -> 15866 | E36: =SUMIF(Data_Entry!$C$5:$C$670,B36,Data_Entry!Q$5:Q$670) -> 15186 | F36: =SUMIF(Data_Entry!$C$5:$C$670,B36,Data_Entry!X$5:X$670) -> 13502 | G36: =D36/C36 -> 1.0406381 | H36: =E36/C36 -> 0.99603749 | I36: =F36/C36 -> 0.88558529 | J36: =SUMIF(Data_Entry!$C$5:$C$670,B36,Data_Entry!AK$5:AK$670) -> 1208.3547 | K36: =SUMIF(Data_Entry!$C$5:$C$670,B36,Data_Entry!AL$5:AL$670) -> 3216 | L36: =IF(((D36-E36)/D36)<0,0,(D36-E36)/D36) -> 0.042858944 | M36: =IF((D36-F36)/D36<0,0,(D36-F36)/D36) -> 0.14899786 | N36: =_xlfn.IFS(G36<95%,"Mauvaise",G36>=95%,"Bonne") -> Bonne | O36: =_xlfn.IFS(L36>10%,"Mauvaise",L36<=10%,"Bonne") -> Bonne | P36: =IF(AND(L36<=10%,G36>=90%),1,IF(AND(L36<=10%,G36<90%),3,IF(AND(L36>10%,G36>=90%),2,IF(AND(L36>10%,G36<90%),4,)))) -> 1 | Q36: =VLOOKUP(B36,Data_Entry!$AO$4:$AZ$38,12,FALSE) -> 0.50592157 | R36: =_xlfn.IFS(P36=1,4,P36=2,3,P36=3,2,P36=4,1) -> 4
... B41: Walikale | C41: =SUMIF(Data_Entry!$C$5:$C$670,B41,Data_Entry!H$5:H$670) -> 6022.9838 | D41: =SUMIF(Data_Entry!$C$5:$C$670,B41,Data_Entry!O$5:O$670) -> 7013 | E41: =SUMIF(Data_Entry!$C$5:$C$670,B41,Data_Entry!Q$5:Q$670) -> 6822 | F41: =SUMIF(Data_Entry!$C$5:$C$670,B41,Data_Entry!X$5:X$670) -> 6082 | G41: =D41/C41 -> 1.164373 | H41: =E41/C41 -> 1.1326612 | I41: =F41/C41 -> 1.0097985 | J41: =SUMIF(Data_Entry!$C$5:$C$670,B41,Data_Entry!AK$5:AK$670) -> 118.87275 | K41: =SUMIF(Data_Entry!$C$5:$C$670,B41,Data_Entry!AL$5:AL$670) -> 1015 | L41: =IF(((D41-E41)/D41)<0,0,(D41-E41)/D41) -> 0.027235135 | M41: =IF((D41-F41)/D41<0,0,(D41-F41)/D41) -> 0.13275346 | N41: =_xlfn.IFS(G41<95%,"Mauvaise",G41>=95%,"Bonne") -> Bonne | O41: =_xlfn.IFS(L41>10%,"Mauvaise",L41<=10%,"Bonne") -> Bonne | P41: =IF(AND(L41<=10%,G41>=90%),1,IF(AND(L41<=10%,G41<90%),3,IF(AND(L41>10%,G41>=90%),2,IF(AND(L41>10%,G41<90%),4,)))) -> 1 | Q41: =VLOOKUP(B41,Data_Entry!$AO$4:$AZ$38,12,FALSE) -> 0 | R41: =_xlfn.IFS(P41=1,4,P41=2,3,P41=3,2,P41=4,1) -> 4
